<?xml version="1.0" ?>
<!-- =================================================================================== -->
<!-- |    This document was autogenerated by xacro from rovo.urdf.xacro                | -->
<!-- |    EDITING THIS FILE BY HAND IS NOT RECOMMENDED                                 | -->
<!-- =================================================================================== -->
<robot name="rovo">
  <link name="left_wheel_va_link">
    <!-- Adding virtual wheels -->
    <!-- <visual>
                <geometry>
                    <mesh filename="package://mbs_rovo_gazebo/robot_gazebo_description/meshes/visual/v_wheel.dae"/>
                </geometry>
                <origin xyz="${l_x} ${l_y} ${l_z}" rpy="${l_roll} ${l_pitch} ${l_yaw}"/>
            </visual> -->
    <collision>
      <geometry>
        <mesh filename="package://mbs_rovo_gazebo/robot_gazebo_description/meshes/collision/v_wheel.stl"/>
      </geometry>
      <origin rpy="0 0 0" xyz="0.2 0 0"/>
    </collision>
    <inertial>
      <mass value="2.0"/>
      <inertia ixx="0.5" ixy="0.00001" ixz="0.0" iyy="0.239" iyz="0.0" izz="0.239"/>
    </inertial>
  </link>
  <joint name="left_wheel_va_joint" type="continuous">
    <parent link="left_axle_link"/>
    <child link="left_wheel_va_link"/>
    <origin rpy="0 0 0" xyz="-0.5 -0.45 -0.1"/>
    <axis xyz="1 0 0"/>
    <limit effort="10000" velocity="1000"/>
    <joint_properties damping="0.0" friction="0.0"/>
  </joint>
  <link name="left_wheel_vb_link">
    <!-- Adding virtual wheels -->
    <!-- <visual>
                <geometry>
                    <mesh filename="package://mbs_rovo_gazebo/robot_gazebo_description/meshes/visual/v_wheel.dae"/>
                </geometry>
                <origin xyz="${l_x} ${l_y} ${l_z}" rpy="${l_roll} ${l_pitch} ${l_yaw}"/>
            </visual> -->
    <collision>
      <geometry>
        <mesh filename="package://mbs_rovo_gazebo/robot_gazebo_description/meshes/collision/v_wheel.stl"/>
      </geometry>
      <origin rpy="0 0 0" xyz="0.2 0 0"/>
    </collision>
    <inertial>
      <mass value="2.0"/>
      <inertia ixx="0.5" ixy="0.00001" ixz="0.0" iyy="0.239" iyz="0.0" izz="0.239"/>
    </inertial>
  </link>
  <joint name="left_wheel_vb_joint" type="continuous">
    <parent link="left_axle_link"/>
    <child link="left_wheel_vb_link"/>
    <origin rpy="0 0 0" xyz="-0.5 0.2 -0.1"/>
    <axis xyz="1 0 0"/>
    <limit effort="10000" velocity="1000"/>
    <joint_properties damping="0.0" friction="0.0"/>
  </joint>
  <link name="left_wheel_vc_link">
    <!-- Adding virtual wheels -->
    <!-- <visual>
                <geometry>
                    <mesh filename="package://mbs_rovo_gazebo/robot_gazebo_description/meshes/visual/v_wheel.dae"/>
                </geometry>
                <origin xyz="${l_x} ${l_y} ${l_z}" rpy="${l_roll} ${l_pitch} ${l_yaw}"/>
            </visual> -->
    <collision>
      <geometry>
        <mesh filename="package://mbs_rovo_gazebo/robot_gazebo_description/meshes/collision/v_wheel.stl"/>
      </geometry>
      <origin rpy="0 0 0" xyz="0.2 0 0"/>
    </collision>
    <inertial>
      <mass value="2.0"/>
      <inertia ixx="0.5" ixy="0.00001" ixz="0.0" iyy="0.239" iyz="0.0" izz="0.239"/>
    </inertial>
  </link>
  <joint name="left_wheel_vc_joint" type="continuous">
    <parent link="left_axle_link"/>
    <child link="left_wheel_vc_link"/>
    <origin rpy="0 0 0" xyz="-0.5 -0.2 -0.1"/>
    <axis xyz="1 0 0"/>
    <limit effort="10000" velocity="1000"/>
    <joint_properties damping="0.0" friction="0.0"/>
  </joint>
  <link name="left_wheel_vg_link">
    <!-- Adding virtual wheels -->
    <!-- <visual>
                <geometry>
                    <mesh filename="package://mbs_rovo_gazebo/robot_gazebo_description/meshes/visual/v_wheel.dae"/>
                </geometry>
                <origin xyz="${l_x} ${l_y} ${l_z}" rpy="${l_roll} ${l_pitch} ${l_yaw}"/>
            </visual> -->
    <collision>
      <geometry>
        <mesh filename="package://mbs_rovo_gazebo/robot_gazebo_description/meshes/collision/v_wheel.stl"/>
      </geometry>
      <origin rpy="0 0 0" xyz="0.2 0 0"/>
    </collision>
    <inertial>
      <mass value="2.0"/>
      <inertia ixx="0.5" ixy="0.00001" ixz="0.0" iyy="0.239" iyz="0.0" izz="0.239"/>
    </inertial>
  </link>
  <joint name="left_wheel_vg_joint" type="continuous">
    <parent link="left_axle_link"/>
    <child link="left_wheel_vg_link"/>
    <origin rpy="0 0 0" xyz="-0.5 0.45 -0.1"/>
    <axis xyz="1 0 0"/>
    <limit effort="10000" velocity="1000"/>
    <joint_properties damping="0.0" friction="0.0"/>
  </joint>
  <link name="left_wheel_vd_link">
    <!-- Adding virtual wheels -->
    <!-- <visual>
                <geometry>
                    <mesh filename="package://mbs_rovo_gazebo/robot_gazebo_description/meshes/visual/v_wheel.dae"/>
                </geometry>
                <origin xyz="${l_x} ${l_y} ${l_z}" rpy="${l_roll} ${l_pitch} ${l_yaw}"/>
            </visual> -->
    <collision>
      <geometry>
        <mesh filename="package://mbs_rovo_gazebo/robot_gazebo_description/meshes/collision/v_wheel.stl"/>
      </geometry>
      <origin rpy="0 0 0" xyz="0.2 0 0"/>
    </collision>
    <inertial>
      <mass value="2.0"/>
      <inertia ixx="0.5" ixy="0.00001" ixz="0.0" iyy="0.239" iyz="0.0" izz="0.239"/>
    </inertial>
  </link>
  <joint name="left_wheel_vd_joint" type="continuous">
    <parent link="left_axle_link"/>
    <child link="left_wheel_vd_link"/>
    <origin rpy="0 0 0" xyz="0.0 -0.45 -0.1"/>
    <axis xyz="1 0 0"/>
    <limit effort="10000" velocity="1000"/>
    <joint_properties damping="0.0" friction="0.0"/>
  </joint>
  <link name="left_wheel_ve_link">
    <!-- Adding virtual wheels -->
    <!-- <visual>
                <geometry>
                    <mesh filename="package://mbs_rovo_gazebo/robot_gazebo_description/meshes/visual/v_wheel.dae"/>
                </geometry>
                <origin xyz="${l_x} ${l_y} ${l_z}" rpy="${l_roll} ${l_pitch} ${l_yaw}"/>
            </visual> -->
    <collision>
      <geometry>
        <mesh filename="package://mbs_rovo_gazebo/robot_gazebo_description/meshes/collision/v_wheel.stl"/>
      </geometry>
      <origin rpy="0 0 0" xyz="0.2 0 0"/>
    </collision>
    <inertial>
      <mass value="2.0"/>
      <inertia ixx="0.5" ixy="0.00001" ixz="0.0" iyy="0.239" iyz="0.0" izz="0.239"/>
    </inertial>
  </link>
  <joint name="left_wheel_ve_joint" type="continuous">
    <parent link="left_axle_link"/>
    <child link="left_wheel_ve_link"/>
    <origin rpy="0 0 0" xyz="0.0 -0.2 -0.1"/>
    <axis xyz="1 0 0"/>
    <limit effort="10000" velocity="1000"/>
    <joint_properties damping="0.0" friction="0.0"/>
  </joint>
  <link name="left_wheel_vf_link">
    <!-- Adding virtual wheels -->
    <!-- <visual>
                <geometry>
                    <mesh filename="package://mbs_rovo_gazebo/robot_gazebo_description/meshes/visual/v_wheel.dae"/>
                </geometry>
                <origin xyz="${l_x} ${l_y} ${l_z}" rpy="${l_roll} ${l_pitch} ${l_yaw}"/>
            </visual> -->
    <collision>
      <geometry>
        <mesh filename="package://mbs_rovo_gazebo/robot_gazebo_description/meshes/collision/v_wheel.stl"/>
      </geometry>
      <origin rpy="0 0 0" xyz="0.2 0 0"/>
    </collision>
    <inertial>
      <mass value="2.0"/>
      <inertia ixx="0.5" ixy="0.00001" ixz="0.0" iyy="0.239" iyz="0.0" izz="0.239"/>
    </inertial>
  </link>
  <joint name="left_wheel_vf_joint" type="continuous">
    <parent link="left_axle_link"/>
    <child link="left_wheel_vf_link"/>
    <origin rpy="0 0 0" xyz="0.0 0.2 -0.1"/>
    <axis xyz="1 0 0"/>
    <limit effort="10000" velocity="1000"/>
    <joint_properties damping="0.0" friction="0.0"/>
  </joint>
  <link name="left_wheel_vh_link">
    <!-- Adding virtual wheels -->
    <!-- <visual>
                <geometry>
                    <mesh filename="package://mbs_rovo_gazebo/robot_gazebo_description/meshes/visual/v_wheel.dae"/>
                </geometry>
                <origin xyz="${l_x} ${l_y} ${l_z}" rpy="${l_roll} ${l_pitch} ${l_yaw}"/>
            </visual> -->
    <collision>
      <geometry>
        <mesh filename="package://mbs_rovo_gazebo/robot_gazebo_description/meshes/collision/v_wheel.stl"/>
      </geometry>
      <origin rpy="0 0 0" xyz="0.2 0 0"/>
    </collision>
    <inertial>
      <mass value="2.0"/>
      <inertia ixx="0.5" ixy="0.00001" ixz="0.0" iyy="0.239" iyz="0.0" izz="0.239"/>
    </inertial>
  </link>
  <joint name="left_wheel_vh_joint" type="continuous">
    <parent link="left_axle_link"/>
    <child link="left_wheel_vh_link"/>
    <origin rpy="0 0 0" xyz="0.0 0.45 -0.1"/>
    <axis xyz="1 0 0"/>
    <limit effort="10000" velocity="1000"/>
    <joint_properties damping="0.0" friction="0.0"/>
  </joint>
  <link name="right_wheel_va_link">
    <!-- Adding virtual wheels -->
    <!-- <visual>
                <geometry>
                    <mesh filename="package://mbs_rovo_gazebo/robot_gazebo_description/meshes/visual/v_wheel.dae"/>
                </geometry>
                <origin xyz="${l_x} ${l_y} ${l_z}" rpy="${l_roll} ${l_pitch} ${l_yaw}"/>
            </visual> -->
    <collision>
      <geometry>
        <mesh filename="package://mbs_rovo_gazebo/robot_gazebo_description/meshes/collision/v_wheel.stl"/>
      </geometry>
      <origin rpy="0 3.14156 0" xyz="-0.2 0 0"/>
    </collision>
    <inertial>
      <mass value="2.0"/>
      <inertia ixx="0.5" ixy="0.00001" ixz="0.0" iyy="0.239" iyz="0.0" izz="0.239"/>
    </inertial>
  </link>
  <joint name="right_wheel_va_joint" type="continuous">
    <parent link="right_axle_link"/>
    <child link="right_wheel_va_link"/>
    <origin rpy="0 0 0" xyz="0.0 -0.45 -0.1"/>
    <axis xyz="1 0 0"/>
    <limit effort="10000" velocity="1000"/>
    <joint_properties damping="0.0" friction="0.0"/>
  </joint>
  <link name="right_wheel_vb_link">
    <!-- Adding virtual wheels -->
    <!-- <visual>
                <geometry>
                    <mesh filename="package://mbs_rovo_gazebo/robot_gazebo_description/meshes/visual/v_wheel.dae"/>
                </geometry>
                <origin xyz="${l_x} ${l_y} ${l_z}" rpy="${l_roll} ${l_pitch} ${l_yaw}"/>
            </visual> -->
    <collision>
      <geometry>
        <mesh filename="package://mbs_rovo_gazebo/robot_gazebo_description/meshes/collision/v_wheel.stl"/>
      </geometry>
      <origin rpy="0 3.14156 0" xyz="-0.2 0 0"/>
    </collision>
    <inertial>
      <mass value="2.0"/>
      <inertia ixx="0.5" ixy="0.00001" ixz="0.0" iyy="0.239" iyz="0.0" izz="0.239"/>
    </inertial>
  </link>
  <joint name="right_wheel_vb_joint" type="continuous">
    <parent link="right_axle_link"/>
    <child link="right_wheel_vb_link"/>
    <origin rpy="0 0 0" xyz="0.0 -0.2 -0.1"/>
    <axis xyz="1 0 0"/>
    <limit effort="10000" velocity="1000"/>
    <joint_properties damping="0.0" friction="0.0"/>
  </joint>
  <link name="right_wheel_vg_link">
    <!-- Adding virtual wheels -->
    <!-- <visual>
                <geometry>
                    <mesh filename="package://mbs_rovo_gazebo/robot_gazebo_description/meshes/visual/v_wheel.dae"/>
                </geometry>
                <origin xyz="${l_x} ${l_y} ${l_z}" rpy="${l_roll} ${l_pitch} ${l_yaw}"/>
            </visual> -->
    <collision>
      <geometry>
        <mesh filename="package://mbs_rovo_gazebo/robot_gazebo_description/meshes/collision/v_wheel.stl"/>
      </geometry>
      <origin rpy="0 3.14156 0" xyz="-0.2 0 0"/>
    </collision>
    <inertial>
      <mass value="2.0"/>
      <inertia ixx="0.5" ixy="0.00001" ixz="0.0" iyy="0.239" iyz="0.0" izz="0.239"/>
    </inertial>
  </link>
  <joint name="right_wheel_vg_joint" type="continuous">
    <parent link="right_axle_link"/>
    <child link="right_wheel_vg_link"/>
    <origin rpy="0 0 0" xyz="0.0 0.2 -0.1"/>
    <axis xyz="1 0 0"/>
    <limit effort="10000" velocity="1000"/>
    <joint_properties damping="0.0" friction="0.0"/>
  </joint>
  <link name="right_wheel_vc_link">
    <!-- Adding virtual wheels -->
    <!-- <visual>
                <geometry>
                    <mesh filename="package://mbs_rovo_gazebo/robot_gazebo_description/meshes/visual/v_wheel.dae"/>
                </geometry>
                <origin xyz="${l_x} ${l_y} ${l_z}" rpy="${l_roll} ${l_pitch} ${l_yaw}"/>
            </visual> -->
    <collision>
      <geometry>
        <mesh filename="package://mbs_rovo_gazebo/robot_gazebo_description/meshes/collision/v_wheel.stl"/>
      </geometry>
      <origin rpy="0 3.14156 0" xyz="-0.2 0 0"/>
    </collision>
    <inertial>
      <mass value="2.0"/>
      <inertia ixx="0.5" ixy="0.00001" ixz="0.0" iyy="0.239" iyz="0.0" izz="0.239"/>
    </inertial>
  </link>
  <joint name="right_wheel_vc_joint" type="continuous">
    <parent link="right_axle_link"/>
    <child link="right_wheel_vc_link"/>
    <origin rpy="0 0 0" xyz="0.0 0.45 -0.1"/>
    <axis xyz="1 0 0"/>
    <limit effort="10000" velocity="1000"/>
    <joint_properties damping="0.0" friction="0.0"/>
  </joint>
  <link name="right_wheel_vd_link">
    <!-- Adding virtual wheels -->
    <!-- <visual>
                <geometry>
                    <mesh filename="package://mbs_rovo_gazebo/robot_gazebo_description/meshes/visual/v_wheel.dae"/>
                </geometry>
                <origin xyz="${l_x} ${l_y} ${l_z}" rpy="${l_roll} ${l_pitch} ${l_yaw}"/>
            </visual> -->
    <collision>
      <geometry>
        <mesh filename="package://mbs_rovo_gazebo/robot_gazebo_description/meshes/collision/v_wheel.stl"/>
      </geometry>
      <origin rpy="0 3.14156 0" xyz="-0.2 0 0"/>
    </collision>
    <inertial>
      <mass value="2.0"/>
      <inertia ixx="0.5" ixy="0.00001" ixz="0.0" iyy="0.239" iyz="0.0" izz="0.239"/>
    </inertial>
  </link>
  <joint name="right_wheel_vd_joint" type="continuous">
    <parent link="right_axle_link"/>
    <child link="right_wheel_vd_link"/>
    <origin rpy="0 0 0" xyz="0.5 -0.45 -0.1"/>
    <axis xyz="1 0 0"/>
    <limit effort="10000" velocity="1000"/>
    <joint_properties damping="0.0" friction="0.0"/>
  </joint>
  <link name="right_wheel_vh_link">
    <!-- Adding virtual wheels -->
    <!-- <visual>
                <geometry>
                    <mesh filename="package://mbs_rovo_gazebo/robot_gazebo_description/meshes/visual/v_wheel.dae"/>
                </geometry>
                <origin xyz="${l_x} ${l_y} ${l_z}" rpy="${l_roll} ${l_pitch} ${l_yaw}"/>
            </visual> -->
    <collision>
      <geometry>
        <mesh filename="package://mbs_rovo_gazebo/robot_gazebo_description/meshes/collision/v_wheel.stl"/>
      </geometry>
      <origin rpy="0 3.14156 0" xyz="-0.2 0 0"/>
    </collision>
    <inertial>
      <mass value="2.0"/>
      <inertia ixx="0.5" ixy="0.00001" ixz="0.0" iyy="0.239" iyz="0.0" izz="0.239"/>
    </inertial>
  </link>
  <joint name="right_wheel_vh_joint" type="continuous">
    <parent link="right_axle_link"/>
    <child link="right_wheel_vh_link"/>
    <origin rpy="0 0 0" xyz="0.5 -0.2 -0.1"/>
    <axis xyz="1 0 0"/>
    <limit effort="10000" velocity="1000"/>
    <joint_properties damping="0.0" friction="0.0"/>
  </joint>
  <link name="right_wheel_ve_link">
    <!-- Adding virtual wheels -->
    <!-- <visual>
                <geometry>
                    <mesh filename="package://mbs_rovo_gazebo/robot_gazebo_description/meshes/visual/v_wheel.dae"/>
                </geometry>
                <origin xyz="${l_x} ${l_y} ${l_z}" rpy="${l_roll} ${l_pitch} ${l_yaw}"/>
            </visual> -->
    <collision>
      <geometry>
        <mesh filename="package://mbs_rovo_gazebo/robot_gazebo_description/meshes/collision/v_wheel.stl"/>
      </geometry>
      <origin rpy="0 3.14156 0" xyz="-0.2 0 0"/>
    </collision>
    <inertial>
      <mass value="2.0"/>
      <inertia ixx="0.5" ixy="0.00001" ixz="0.0" iyy="0.239" iyz="0.0" izz="0.239"/>
    </inertial>
  </link>
  <joint name="right_wheel_ve_joint" type="continuous">
    <parent link="right_axle_link"/>
    <child link="right_wheel_ve_link"/>
    <origin rpy="0 0 0" xyz="0.5 0.2 -0.1"/>
    <axis xyz="1 0 0"/>
    <limit effort="10000" velocity="1000"/>
    <joint_properties damping="0.0" friction="0.0"/>
  </joint>
  <link name="right_wheel_vf_link">
    <!-- Adding virtual wheels -->
    <!-- <visual>
                <geometry>
                    <mesh filename="package://mbs_rovo_gazebo/robot_gazebo_description/meshes/visual/v_wheel.dae"/>
                </geometry>
                <origin xyz="${l_x} ${l_y} ${l_z}" rpy="${l_roll} ${l_pitch} ${l_yaw}"/>
            </visual> -->
    <collision>
      <geometry>
        <mesh filename="package://mbs_rovo_gazebo/robot_gazebo_description/meshes/collision/v_wheel.stl"/>
      </geometry>
      <origin rpy="0 3.14156 0" xyz="-0.2 0 0"/>
    </collision>
    <inertial>
      <mass value="2.0"/>
      <inertia ixx="0.5" ixy="0.00001" ixz="0.0" iyy="0.239" iyz="0.0" izz="0.239"/>
    </inertial>
  </link>
  <joint name="right_wheel_vf_joint" type="continuous">
    <parent link="right_axle_link"/>
    <child link="right_wheel_vf_link"/>
    <origin rpy="0 0 0" xyz="0.5 0.45 -0.1"/>
    <axis xyz="1 0 0"/>
    <limit effort="10000" velocity="1000"/>
    <joint_properties damping="0.0" friction="0.0"/>
  </joint>
  <link name="base_link"/>
  <link name="orientation_link"/>
  <joint name="orientation_joint" type="fixed">
    <parent link="base_link"/>
    <child link="orientation_link"/>
    <origin rpy="0 0 1.5708" xyz="0 0 0"/>
  </joint>
  <link name="chasis_link">
    <!-- Adding visual and collision elements -->
    <visual>
      <geometry>
        <mesh filename="package://mbs_rovo_gazebo/robot_gazebo_description/meshes/visual/chasis.dae"/>
      </geometry>
      <origin rpy="0 0 0" xyz="0 0 0"/>
    </visual>
    <collision>
      <geometry>
        <mesh filename="package://mbs_rovo_gazebo/robot_gazebo_description/meshes/collision/chasis.stl"/>
      </geometry>
      <origin rpy="0 0 0" xyz="0 0 0"/>
    </collision>
    <inertial>
      <mass value="33.0"/>
      <inertia ixx="1.61221" ixy="-0.0" ixz="0.0" iyy="0.55299" iyz="-0.07623" izz="1.84073"/>
    </inertial>
  </link>
  <joint name="chasis_joint" type="fixed">
    <parent link="orientation_link"/>
    <child link="chasis_link"/>
    <origin rpy="0 0 0" xyz="0 0 0.18"/>
    <axis xyz="1 0 0"/>
  </joint>
  <link name="control_box_link">
    <!-- Adding visual and collision elements -->
    <visual>
      <geometry>
        <mesh filename="package://mbs_rovo_gazebo/robot_gazebo_description/meshes/visual/control_box.dae"/>
      </geometry>
      <origin rpy="0 0 0" xyz="0 0 0"/>
    </visual>
    <collision>
      <geometry>
        <mesh filename="package://mbs_rovo_gazebo/robot_gazebo_description/meshes/collision/control_box.stl"/>
      </geometry>
      <origin rpy="0 0 0" xyz="0 0 0"/>
    </collision>
    <inertial>
      <mass value="19.0"/>
      <inertia ixx="0.599" ixy="-0.00099" ixz="-0.0032" iyy="0.19332" iyz="0.00271" izz="0.7615"/>
    </inertial>
  </link>
  <joint name="control_box_joint" type="fixed">
    <parent link="chasis_link"/>
    <child link="control_box_link"/>
    <origin rpy="0 0 0" xyz="-0.01807 -0.14018 0.20167"/>
    <axis xyz="1 0 0"/>
  </joint>
  <link name="body_link">
    <!-- Adding visual and collision elements -->
    <visual>
      <geometry>
        <mesh filename="package://mbs_rovo_gazebo/robot_gazebo_description/meshes/visual/body.dae"/>
      </geometry>
      <origin rpy="0 0 0" xyz="0 0 0"/>
    </visual>
    <collision>
      <geometry>
        <mesh filename="package://mbs_rovo_gazebo/robot_gazebo_description/meshes/collision/body.stl"/>
      </geometry>
      <origin rpy="0 0 0" xyz="0 0 0"/>
    </collision>
    <inertial>
      <mass value="18.0"/>
      <inertia ixx="1.53203" ixy="-0.00008" ixz="0.00099" iyy="0.39248" iyz="-0.25492" izz="1.60665"/>
    </inertial>
  </link>
  <joint name="body_joint" type="fixed">
    <parent link="chasis_link"/>
    <child link="body_link"/>
    <origin rpy="0 0 0" xyz="-0.00067 0.04315 0.23273"/>
    <axis xyz="1 0 0"/>
  </joint>
  <link name="right_shaft_link">
    <!-- Adding visual and collision elements -->
    <visual>
      <geometry>
        <mesh filename="package://mbs_rovo_gazebo/robot_gazebo_description/meshes/visual/shaft.dae"/>
      </geometry>
      <origin rpy="0 0 0" xyz="0 0 0"/>
    </visual>
    <collision>
      <geometry>
        <mesh filename="package://mbs_rovo_gazebo/robot_gazebo_description/meshes/collision/shaft.stl"/>
      </geometry>
      <origin rpy="0 0 0" xyz="0 0 0"/>
    </collision>
    <inertial>
      <mass value="0.9426"/>
      <inertia ixx="0.00079" ixy="-0.00007" ixz="0.00032" iyy="0.00146" iyz="0.00003" izz="0.00201"/>
    </inertial>
  </link>
  <joint name="right_shaft_joint" type="fixed">
    <parent link="chasis_link"/>
    <child link="right_shaft_link"/>
    <origin rpy="0 0 0" xyz="-0.26654 -0.00251 0.08556"/>
    <axis xyz="1 0 0"/>
  </joint>
  <link name="left_shaft_link">
    <!-- Adding visual and collision elements -->
    <visual>
      <geometry>
        <mesh filename="package://mbs_rovo_gazebo/robot_gazebo_description/meshes/visual/shaft.dae"/>
      </geometry>
      <origin rpy="0 0 0" xyz="0 0 0"/>
    </visual>
    <collision>
      <geometry>
        <mesh filename="package://mbs_rovo_gazebo/robot_gazebo_description/meshes/collision/shaft.stl"/>
      </geometry>
      <origin rpy="0 0 0" xyz="0 0 0"/>
    </collision>
    <inertial>
      <mass value="0.9426"/>
      <inertia ixx="0.00079" ixy="-0.00007" ixz="0.00032" iyy="0.00146" iyz="0.00003" izz="0.00201"/>
    </inertial>
  </link>
  <joint name="left_shaft_joint" type="fixed">
    <parent link="chasis_link"/>
    <child link="left_shaft_link"/>
    <origin rpy="0 0 0" xyz="0.26654 -0.00251 0.08556"/>
    <axis xyz="1 0 0"/>
  </joint>
  <link name="right_suspension_link">
    <!-- Adding visual and collision elements -->
    <visual>
      <geometry>
        <mesh filename="package://mbs_rovo_gazebo/robot_gazebo_description/meshes/visual/suspension.dae"/>
      </geometry>
      <origin rpy="0.0 0.0 0" xyz="0 0 0"/>
    </visual>
    <collision>
      <geometry>
        <mesh filename="package://mbs_rovo_gazebo/robot_gazebo_description/meshes/collision/suspension.stl"/>
      </geometry>
      <origin rpy="0.0 0.0 0" xyz="0 0 0"/>
    </collision>
    <inertial>
      <mass value="1.3979"/>
      <inertia ixx="0.0049" ixy="0.00326" ixz="0.00001" iyy="0.00733" iyz="-0.00001" izz="0.00294"/>
    </inertial>
  </link>
  <joint name="right_suspension_joint" type="fixed">
    <parent link="chasis_link"/>
    <child link="right_suspension_link"/>
    <origin rpy="0 0 0" xyz="-0.30223 0.05159 0.09956"/>
    <axis xyz="1 0 0"/>
  </joint>
  <link name="left_suspension_link">
    <!-- Adding visual and collision elements -->
    <visual>
      <geometry>
        <mesh filename="package://mbs_rovo_gazebo/robot_gazebo_description/meshes/visual/suspension.dae"/>
      </geometry>
      <origin rpy="3.14159 3.14159 0" xyz="0 0 0"/>
    </visual>
    <collision>
      <geometry>
        <mesh filename="package://mbs_rovo_gazebo/robot_gazebo_description/meshes/collision/suspension.stl"/>
      </geometry>
      <origin rpy="3.14159 3.14159 0" xyz="0 0 0"/>
    </collision>
    <inertial>
      <mass value="1.3979"/>
      <inertia ixx="0.0049" ixy="0.00326" ixz="0.00001" iyy="0.00733" iyz="-0.00001" izz="0.00294"/>
    </inertial>
  </link>
  <joint name="left_suspension_joint" type="fixed">
    <parent link="chasis_link"/>
    <child link="left_suspension_link"/>
    <origin rpy="0 0 0" xyz="0.30223 0.05159 0.09956"/>
    <axis xyz="1 0 0"/>
  </joint>
  <link name="right_wishbone_link">
    <!-- Adding visual and collision elements -->
    <visual>
      <geometry>
        <mesh filename="package://mbs_rovo_gazebo/robot_gazebo_description/meshes/visual/wishbone.dae"/>
      </geometry>
      <origin rpy="0 0.0 0" xyz="0 0 0"/>
    </visual>
    <collision>
      <geometry>
        <mesh filename="package://mbs_rovo_gazebo/robot_gazebo_description/meshes/collision/wishbone.stl"/>
      </geometry>
      <origin rpy="0 0.0 0" xyz="0 0 0"/>
    </collision>
    <inertial>
      <mass value="5.8006"/>
      <inertia ixx="0.20112" ixy="0.0009" ixz="-0.0003" iyy="0.01785" iyz="-0.00013" izz="0.21723"/>
    </inertial>
  </link>
  <joint name="right_wishbone_joint" type="fixed">
    <parent link="chasis_link"/>
    <child link="right_wishbone_link"/>
    <origin rpy="0 0 0" xyz="-0.37227 -0.03549 -0.04509"/>
    <axis xyz="1 0 0"/>
  </joint>
  <link name="left_wishbone_link">
    <!-- Adding visual and collision elements -->
    <visual>
      <geometry>
        <mesh filename="package://mbs_rovo_gazebo/robot_gazebo_description/meshes/visual/wishbone.dae"/>
      </geometry>
      <origin rpy="0 3.14159 0" xyz="0 0 0"/>
    </visual>
    <collision>
      <geometry>
        <mesh filename="package://mbs_rovo_gazebo/robot_gazebo_description/meshes/collision/wishbone.stl"/>
      </geometry>
      <origin rpy="0 3.14159 0" xyz="0 0 0"/>
    </collision>
    <inertial>
      <mass value="5.8006"/>
      <inertia ixx="0.20112" ixy="0.0009" ixz="-0.0003" iyy="0.01785" iyz="-0.00013" izz="0.21723"/>
    </inertial>
  </link>
  <joint name="left_wishbone_joint" type="fixed">
    <parent link="chasis_link"/>
    <child link="left_wishbone_link"/>
    <origin rpy="0 0 0" xyz="0.37227 -0.03549 -0.04509"/>
    <axis xyz="1 0 0"/>
  </joint>
  <link name="right_axle_link">
    <!-- Adding visual and collision elements -->
    <visual>
      <geometry>
        <mesh filename="package://mbs_rovo_gazebo/robot_gazebo_description/meshes/visual/right_axle.dae"/>
      </geometry>
      <origin rpy="0 0 0" xyz="0 0 0"/>
    </visual>
    <inertial>
      <mass value="13.0"/>
      <inertia ixx="1.13189" ixy="-0.02308" ixz="0.01185" iyy="0.08915" iyz="0.04378" izz="1.07262"/>
    </inertial>
  </link>
  <joint name="right_axle_joint" type="fixed">
    <parent link="right_wishbone_link"/>
    <child link="right_axle_link"/>
    <origin rpy="0 0 0" xyz="-0.08759 0.01321 -0.01819"/>
    <axis xyz="1 0 0"/>
  </joint>
  <link name="right_track_link">
    <!-- Adding visual and collision elements -->
    <visual>
      <geometry>
        <mesh filename="package://mbs_rovo_gazebo/robot_gazebo_description/meshes/visual/track.dae"/>
      </geometry>
      <origin rpy="0 0 0" xyz="0 0 0"/>
    </visual>
    <inertial>
      <mass value="37.8"/>
      <inertia ixx="3.65739" ixy="-0.00106" ixz="0.002" iyy="0.86184" iyz="0.23514" izz="3.16669"/>
    </inertial>
  </link>
  <joint name="right_track_joint" type="fixed">
    <parent link="right_axle_link"/>
    <child link="right_track_link"/>
    <origin rpy="0 0 0" xyz="0.01108 -0.03237 0.06003"/>
    <axis xyz="1 0 0"/>
  </joint>
  <link name="right_motor_link">
    <!-- Adding visual and collision elements -->
    <visual>
      <geometry>
        <mesh filename="package://mbs_rovo_gazebo/robot_gazebo_description/meshes/visual/motor.dae"/>
      </geometry>
      <origin rpy="0.0 0.0 0" xyz="0 0 0"/>
    </visual>
    <collision>
      <geometry>
        <mesh filename="package://mbs_rovo_gazebo/robot_gazebo_description/meshes/collision/motor.stl"/>
      </geometry>
      <origin rpy="0.0 0.0 0" xyz="0 0 0"/>
    </collision>
    <inertial>
      <mass value="20.0"/>
      <inertia ixx="0.10263" ixy="0.0109" ixz="0.00425" iyy="0.16523" iyz="-0.00794" izz="0.15137"/>
    </inertial>
  </link>
  <joint name="right_motor_joint" type="fixed">
    <parent link="right_axle_link"/>
    <child link="right_motor_link"/>
    <origin rpy="0 0 0" xyz="0.09597 -0.13149 0.18594"/>
    <axis xyz="1 0 0"/>
  </joint>
  <link name="right_mutator_link">
    <!-- Adding visual and collision elements -->
    <visual>
      <geometry>
        <mesh filename="package://mbs_rovo_gazebo/robot_gazebo_description/meshes/visual/mutator.dae"/>
      </geometry>
      <origin rpy="0 0.0 0" xyz="0 0 0"/>
    </visual>
    <collision>
      <geometry>
        <mesh filename="package://mbs_rovo_gazebo/robot_gazebo_description/meshes/collision/mutator.stl"/>
      </geometry>
      <origin rpy="0 0.0 0" xyz="0 0 0"/>
    </collision>
    <inertial>
      <mass value="8.0"/>
      <inertia ixx="0.09715" ixy="0.0" ixz="0.0" iyy="0.0554" iyz="0.0" izz="0.0554"/>
    </inertial>
  </link>
  <joint name="right_mutator_joint" type="continuous">
    <parent link="right_motor_link"/>
    <child link="right_mutator_link"/>
    <origin rpy="0 0 0" xyz="-0.13915 -0.00289 -0.0054"/>
    <axis xyz="1 0 0"/>
  </joint>
  <link name="right_wheel_a_link">
    <!-- Adding visual and collision elements -->
    <visual>
      <geometry>
        <mesh filename="package://mbs_rovo_gazebo/robot_gazebo_description/meshes/visual/front_wheel.dae"/>
      </geometry>
      <origin rpy="0 0 0" xyz="0 0 0"/>
    </visual>
    <collision>
      <geometry>
        <mesh filename="package://mbs_rovo_gazebo/robot_gazebo_description/meshes/collision/front_wheel.stl"/>
      </geometry>
      <origin rpy="0 0 0" xyz="0 0 0"/>
    </collision>
    <inertial>
      <mass value="1.0"/>
      <inertia ixx="0.00458" ixy="0.00001" ixz="-0.0" iyy="0.00239" iyz="-0.0" izz="0.00239"/>
    </inertial>
  </link>
  <joint name="right_wheel_a_joint" type="continuous">
    <parent link="right_axle_link"/>
    <child link="right_wheel_a_link"/>
    <origin rpy="0 0 0" xyz="0.06944 -0.43769 0.00157"/>
    <axis xyz="1 0 0"/>
    <mimic joint="right_mutator_joint" multiplier="1" offset="0"/>
    <limit effort="10000" velocity="1000"/>
    <joint_properties damping="1.0" friction="1.0"/>
  </joint>
  <link name="right_wheel_b_link">
    <!-- Adding visual and collision elements -->
    <visual>
      <geometry>
        <mesh filename="package://mbs_rovo_gazebo/robot_gazebo_description/meshes/visual/rare_wheel.dae"/>
      </geometry>
      <origin rpy="0 0 0" xyz="0 0 0"/>
    </visual>
    <collision>
      <geometry>
        <mesh filename="package://mbs_rovo_gazebo/robot_gazebo_description/meshes/collision/rare_wheel.stl"/>
      </geometry>
      <origin rpy="0 0 0" xyz="0 0 0"/>
    </collision>
    <inertial>
      <mass value="0.5"/>
      <inertia ixx="0.00094" ixy="0.0" ixz="-0.0" iyy="0.00052" iyz="-0.0" izz="0.00052"/>
    </inertial>
  </link>
  <joint name="right_wheel_b_joint" type="continuous">
    <parent link="right_axle_link"/>
    <child link="right_wheel_b_link"/>
    <origin rpy="0 0 0" xyz="0.06922 -0.24269 -0.04742"/>
    <axis xyz="1 0 0"/>
    <mimic joint="right_mutator_joint" multiplier="1" offset="0"/>
    <limit effort="10000" velocity="1000"/>
    <joint_properties damping="1.0" friction="1.0"/>
  </joint>
  <link name="right_wheel_c_link">
    <!-- Adding visual and collision elements -->
    <visual>
      <geometry>
        <mesh filename="package://mbs_rovo_gazebo/robot_gazebo_description/meshes/visual/rare_wheel.dae"/>
      </geometry>
      <origin rpy="0 0 0" xyz="0 0 0"/>
    </visual>
    <collision>
      <geometry>
        <mesh filename="package://mbs_rovo_gazebo/robot_gazebo_description/meshes/collision/rare_wheel.stl"/>
      </geometry>
      <origin rpy="0 0 0" xyz="0 0 0"/>
    </collision>
    <inertial>
      <mass value="0.5"/>
      <inertia ixx="0.00094" ixy="0.0" ixz="-0.0" iyy="0.00052" iyz="-0.0" izz="0.00052"/>
    </inertial>
  </link>
  <joint name="right_wheel_c_joint" type="continuous">
    <parent link="right_axle_link"/>
    <child link="right_wheel_c_link"/>
    <origin rpy="0 0 0" xyz="0.06923 -0.08468 -0.04742"/>
    <axis xyz="1 0 0"/>
    <mimic joint="right_mutator_joint" multiplier="1" offset="0"/>
    <limit effort="10000" velocity="1000"/>
    <joint_properties damping="1.0" friction="1.0"/>
  </joint>
  <link name="right_wheel_d_link">
    <!-- Adding visual and collision elements -->
    <visual>
      <geometry>
        <mesh filename="package://mbs_rovo_gazebo/robot_gazebo_description/meshes/visual/rare_wheel.dae"/>
      </geometry>
      <origin rpy="0 0 0" xyz="0 0 0"/>
    </visual>
    <collision>
      <geometry>
        <mesh filename="package://mbs_rovo_gazebo/robot_gazebo_description/meshes/collision/rare_wheel.stl"/>
      </geometry>
      <origin rpy="0 0 0" xyz="0 0 0"/>
    </collision>
    <inertial>
      <mass value="0.5"/>
      <inertia ixx="0.00094" ixy="0.0" ixz="-0.0" iyy="0.00052" iyz="-0.0" izz="0.00052"/>
    </inertial>
  </link>
  <joint name="right_wheel_d_joint" type="continuous">
    <parent link="right_axle_link"/>
    <child link="right_wheel_d_link"/>
    <origin rpy="0 0 0" xyz="0.06923 0.07333 -0.04743"/>
    <axis xyz="1 0 0"/>
    <mimic joint="right_mutator_joint" multiplier="1" offset="0"/>
    <limit effort="10000" velocity="1000"/>
    <joint_properties damping="1.0" friction="1.0"/>
  </joint>
  <link name="right_wheel_e_link">
    <!-- Adding visual and collision elements -->
    <visual>
      <geometry>
        <mesh filename="package://mbs_rovo_gazebo/robot_gazebo_description/meshes/visual/rare_wheel.dae"/>
      </geometry>
      <origin rpy="0 0 0" xyz="0 0 0"/>
    </visual>
    <collision>
      <geometry>
        <mesh filename="package://mbs_rovo_gazebo/robot_gazebo_description/meshes/collision/rare_wheel.stl"/>
      </geometry>
      <origin rpy="0 0 0" xyz="0 0 0"/>
    </collision>
    <inertial>
      <mass value="0.5"/>
      <inertia ixx="0.00094" ixy="0.0" ixz="-0.0" iyy="0.00052" iyz="-0.0" izz="0.00052"/>
    </inertial>
  </link>
  <joint name="right_wheel_e_joint" type="continuous">
    <parent link="right_axle_link"/>
    <child link="right_wheel_e_link"/>
    <origin rpy="0 0 0" xyz="0.06923 0.23132 -0.04744"/>
    <axis xyz="1 0 0"/>
    <mimic joint="right_mutator_joint" multiplier="1" offset="0"/>
    <limit effort="10000" velocity="1000"/>
    <joint_properties damping="1.0" friction="1.0"/>
  </joint>
  <link name="right_wheel_f_link">
    <!-- Adding visual and collision elements -->
    <visual>
      <geometry>
        <mesh filename="package://mbs_rovo_gazebo/robot_gazebo_description/meshes/visual/rare_wheel.dae"/>
      </geometry>
      <origin rpy="0 0 0" xyz="0 0 0"/>
    </visual>
    <collision>
      <geometry>
        <mesh filename="package://mbs_rovo_gazebo/robot_gazebo_description/meshes/collision/rare_wheel.stl"/>
      </geometry>
      <origin rpy="0 0 0" xyz="0 0 0"/>
    </collision>
    <inertial>
      <mass value="0.5"/>
      <inertia ixx="0.00094" ixy="0.0" ixz="-0.0" iyy="0.00052" iyz="-0.0" izz="0.00052"/>
    </inertial>
  </link>
  <joint name="right_wheel_f_joint" type="continuous">
    <parent link="right_axle_link"/>
    <child link="right_wheel_f_link"/>
    <origin rpy="0 0 0" xyz="0.06915 0.45123 -0.03694"/>
    <axis xyz="1 0 0"/>
    <mimic joint="right_mutator_joint" multiplier="1" offset="0"/>
    <limit effort="10000" velocity="1000"/>
    <joint_properties damping="1.0" friction="1.0"/>
  </joint>
  <link name="right_wheel_g_link">
    <!-- Adding visual and collision elements -->
    <visual>
      <geometry>
        <mesh filename="package://mbs_rovo_gazebo/robot_gazebo_description/meshes/visual/front_wheel.dae"/>
      </geometry>
      <origin rpy="0 3.14156 0" xyz="0 0 0"/>
    </visual>
    <collision>
      <geometry>
        <mesh filename="package://mbs_rovo_gazebo/robot_gazebo_description/meshes/collision/front_wheel.stl"/>
      </geometry>
      <origin rpy="0 3.14156 0" xyz="0 0 0"/>
    </collision>
    <inertial>
      <mass value="1.0"/>
      <inertia ixx="0.00458" ixy="0.00001" ixz="-0.0" iyy="0.00239" iyz="-0.0" izz="0.00239"/>
    </inertial>
  </link>
  <joint name="right_wheel_g_joint" type="continuous">
    <parent link="right_axle_link"/>
    <child link="right_wheel_g_link"/>
    <origin rpy="0 0 0" xyz="-0.07296 -0.43768 0.00156"/>
    <axis xyz="1 0 0"/>
    <mimic joint="right_mutator_joint" multiplier="1" offset="0"/>
    <limit effort="10000" velocity="1000"/>
    <joint_properties damping="1.0" friction="1.0"/>
  </joint>
  <link name="right_wheel_h_link">
    <!-- Adding visual and collision elements -->
    <visual>
      <geometry>
        <mesh filename="package://mbs_rovo_gazebo/robot_gazebo_description/meshes/visual/rare_wheel.dae"/>
      </geometry>
      <origin rpy="0 3.14156 0" xyz="0 0 0"/>
    </visual>
    <collision>
      <geometry>
        <mesh filename="package://mbs_rovo_gazebo/robot_gazebo_description/meshes/collision/rare_wheel.stl"/>
      </geometry>
      <origin rpy="0 3.14156 0" xyz="0 0 0"/>
    </collision>
    <inertial>
      <mass value="0.5"/>
      <inertia ixx="0.00094" ixy="0.0" ixz="-0.0" iyy="0.00052" iyz="-0.0" izz="0.00052"/>
    </inertial>
  </link>
  <joint name="right_wheel_h_joint" type="continuous">
    <parent link="right_axle_link"/>
    <child link="right_wheel_h_link"/>
    <origin rpy="0 0 0" xyz="-0.07275 -0.24269 -0.04742"/>
    <axis xyz="1 0 0"/>
    <mimic joint="right_mutator_joint" multiplier="1" offset="0"/>
    <limit effort="10000" velocity="1000"/>
    <joint_properties damping="1.0" friction="1.0"/>
  </joint>
  <link name="right_wheel_i_link">
    <!-- Adding visual and collision elements -->
    <visual>
      <geometry>
        <mesh filename="package://mbs_rovo_gazebo/robot_gazebo_description/meshes/visual/rare_wheel.dae"/>
      </geometry>
      <origin rpy="0 3.14156 0" xyz="0 0 0"/>
    </visual>
    <collision>
      <geometry>
        <mesh filename="package://mbs_rovo_gazebo/robot_gazebo_description/meshes/collision/rare_wheel.stl"/>
      </geometry>
      <origin rpy="0 3.14156 0" xyz="0 0 0"/>
    </collision>
    <inertial>
      <mass value="0.5"/>
      <inertia ixx="0.00094" ixy="0.0" ixz="-0.0" iyy="0.00052" iyz="-0.0" izz="0.00052"/>
    </inertial>
  </link>
  <joint name="right_wheel_i_joint" type="continuous">
    <parent link="right_axle_link"/>
    <child link="right_wheel_i_link"/>
    <origin rpy="0 0 0" xyz="-0.07274 -0.08468 -0.04742"/>
    <axis xyz="1 0 0"/>
    <mimic joint="right_mutator_joint" multiplier="1" offset="0"/>
    <limit effort="10000" velocity="1000"/>
    <joint_properties damping="1.0" friction="1.0"/>
  </joint>
  <link name="right_wheel_j_link">
    <!-- Adding visual and collision elements -->
    <visual>
      <geometry>
        <mesh filename="package://mbs_rovo_gazebo/robot_gazebo_description/meshes/visual/rare_wheel.dae"/>
      </geometry>
      <origin rpy="0 3.14156 0" xyz="0 0 0"/>
    </visual>
    <collision>
      <geometry>
        <mesh filename="package://mbs_rovo_gazebo/robot_gazebo_description/meshes/collision/rare_wheel.stl"/>
      </geometry>
      <origin rpy="0 3.14156 0" xyz="0 0 0"/>
    </collision>
    <inertial>
      <mass value="0.5"/>
      <inertia ixx="0.00094" ixy="0.0" ixz="-0.0" iyy="0.00052" iyz="-0.0" izz="0.00052"/>
    </inertial>
  </link>
  <joint name="right_wheel_j_joint" type="continuous">
    <parent link="right_axle_link"/>
    <child link="right_wheel_j_link"/>
    <origin rpy="0 0 0" xyz="-0.07274 0.07333 -0.04743"/>
    <axis xyz="1 0 0"/>
    <mimic joint="right_mutator_joint" multiplier="1" offset="0"/>
    <limit effort="10000" velocity="1000"/>
    <joint_properties damping="1.0" friction="1.0"/>
  </joint>
  <link name="right_wheel_k_link">
    <!-- Adding visual and collision elements -->
    <visual>
      <geometry>
        <mesh filename="package://mbs_rovo_gazebo/robot_gazebo_description/meshes/visual/rare_wheel.dae"/>
      </geometry>
      <origin rpy="0 3.14156 0" xyz="0 0 0"/>
    </visual>
    <collision>
      <geometry>
        <mesh filename="package://mbs_rovo_gazebo/robot_gazebo_description/meshes/collision/rare_wheel.stl"/>
      </geometry>
      <origin rpy="0 3.14156 0" xyz="0 0 0"/>
    </collision>
    <inertial>
      <mass value="0.5"/>
      <inertia ixx="0.00094" ixy="0.0" ixz="-0.0" iyy="0.00052" iyz="-0.0" izz="0.00052"/>
    </inertial>
  </link>
  <joint name="right_wheel_k_joint" type="continuous">
    <parent link="right_axle_link"/>
    <child link="right_wheel_k_link"/>
    <origin rpy="0 0 0" xyz="-0.07274 0.23132 -0.04744"/>
    <axis xyz="1 0 0"/>
    <mimic joint="right_mutator_joint" multiplier="1" offset="0"/>
    <limit effort="10000" velocity="1000"/>
    <joint_properties damping="1.0" friction="1.0"/>
  </joint>
  <link name="right_wheel_l_link">
    <!-- Adding visual and collision elements -->
    <visual>
      <geometry>
        <mesh filename="package://mbs_rovo_gazebo/robot_gazebo_description/meshes/visual/rare_wheel.dae"/>
      </geometry>
      <origin rpy="0 3.14156 0" xyz="0 0 0"/>
    </visual>
    <collision>
      <geometry>
        <mesh filename="package://mbs_rovo_gazebo/robot_gazebo_description/meshes/collision/rare_wheel.stl"/>
      </geometry>
      <origin rpy="0 3.14156 0" xyz="0 0 0"/>
    </collision>
    <inertial>
      <mass value="0.5"/>
      <inertia ixx="0.00094" ixy="0.0" ixz="-0.0" iyy="0.00052" iyz="-0.0" izz="0.00052"/>
    </inertial>
  </link>
  <joint name="right_wheel_l_joint" type="continuous">
    <parent link="right_axle_link"/>
    <child link="right_wheel_l_link"/>
    <origin rpy="0 0 0" xyz="-0.07267 0.4512 -0.03695"/>
    <axis xyz="1 0 0"/>
    <mimic joint="right_mutator_joint" multiplier="1" offset="0"/>
    <limit effort="10000" velocity="1000"/>
    <joint_properties damping="1.0" friction="1.0"/>
  </joint>
  <link name="left_axle_link">
    <!-- Adding visual and collision elements -->
    <visual>
      <geometry>
        <mesh filename="package://mbs_rovo_gazebo/robot_gazebo_description/meshes/visual/left_axle.dae"/>
      </geometry>
      <origin rpy="0 0 0" xyz="0 0 0"/>
    </visual>
    <inertial>
      <mass value="13.0"/>
      <inertia ixx="1.13189" ixy="-0.02308" ixz="0.01185" iyy="0.08915" iyz="0.04378" izz="1.07262"/>
    </inertial>
  </link>
  <joint name="left_axle_joint" type="fixed">
    <parent link="left_wishbone_link"/>
    <child link="left_axle_link"/>
    <origin rpy="0 0 0" xyz="0.08759 0.01321 -0.01819"/>
    <axis xyz="1 0 0"/>
  </joint>
  <link name="left_track_link">
    <!-- Adding visual and collision elements -->
    <visual>
      <geometry>
        <mesh filename="package://mbs_rovo_gazebo/robot_gazebo_description/meshes/visual/track.dae"/>
      </geometry>
      <origin rpy="0 0 0" xyz="0 0 0"/>
    </visual>
    <inertial>
      <mass value="37.8"/>
      <inertia ixx="3.65739" ixy="-0.00106" ixz="0.002" iyy="0.86184" iyz="0.23514" izz="3.16669"/>
    </inertial>
  </link>
  <joint name="left_track_joint" type="fixed">
    <parent link="left_axle_link"/>
    <child link="left_track_link"/>
    <origin rpy="0 0 0" xyz="0.01108 -0.03237 0.06003"/>
    <axis xyz="1 0 0"/>
  </joint>
  <link name="left_motor_link">
    <!-- Adding visual and collision elements -->
    <visual>
      <geometry>
        <mesh filename="package://mbs_rovo_gazebo/robot_gazebo_description/meshes/visual/motor.dae"/>
      </geometry>
      <origin rpy="3.14159 3.14159 0" xyz="0 0 0"/>
    </visual>
    <collision>
      <geometry>
        <mesh filename="package://mbs_rovo_gazebo/robot_gazebo_description/meshes/collision/motor.stl"/>
      </geometry>
      <origin rpy="3.14159 3.14159 0" xyz="0 0 0"/>
    </collision>
    <inertial>
      <mass value="20.0"/>
      <inertia ixx="0.10263" ixy="0.0109" ixz="0.00425" iyy="0.16523" iyz="-0.00794" izz="0.15137"/>
    </inertial>
  </link>
  <joint name="left_motor_joint" type="fixed">
    <parent link="left_axle_link"/>
    <child link="left_motor_link"/>
    <origin rpy="0 0 0" xyz="-0.09597 -0.13149 0.18594"/>
    <axis xyz="1 0 0"/>
  </joint>
  <link name="left_mutator_link">
    <!-- Adding visual and collision elements -->
    <visual>
      <geometry>
        <mesh filename="package://mbs_rovo_gazebo/robot_gazebo_description/meshes/visual/mutator.dae"/>
      </geometry>
      <origin rpy="0 3.14159 0" xyz="0 0 0"/>
    </visual>
    <collision>
      <geometry>
        <mesh filename="package://mbs_rovo_gazebo/robot_gazebo_description/meshes/collision/mutator.stl"/>
      </geometry>
      <origin rpy="0 3.14159 0" xyz="0 0 0"/>
    </collision>
    <inertial>
      <mass value="8.0"/>
      <inertia ixx="0.09715" ixy="0.0" ixz="0.0" iyy="0.0554" iyz="0.0" izz="0.0554"/>
    </inertial>
  </link>
  <joint name="left_mutator_joint" type="continuous">
    <parent link="left_motor_link"/>
    <child link="left_mutator_link"/>
    <origin rpy="0 0 0" xyz="0.13915 -0.00289 -0.0054"/>
    <axis xyz="1 0 0"/>
  </joint>
  <link name="left_wheel_a_link">
    <!-- Adding visual and collision elements -->
    <visual>
      <geometry>
        <mesh filename="package://mbs_rovo_gazebo/robot_gazebo_description/meshes/visual/front_wheel.dae"/>
      </geometry>
      <origin rpy="0 0 0" xyz="0 0 0"/>
    </visual>
    <collision>
      <geometry>
        <mesh filename="package://mbs_rovo_gazebo/robot_gazebo_description/meshes/collision/front_wheel.stl"/>
      </geometry>
      <origin rpy="0 0 0" xyz="0 0 0"/>
    </collision>
    <inertial>
      <mass value="1.0"/>
      <inertia ixx="0.00458" ixy="0.00001" ixz="-0.0" iyy="0.00239" iyz="-0.0" izz="0.00239"/>
    </inertial>
  </link>
  <joint name="left_wheel_a_joint" type="continuous">
    <parent link="left_axle_link"/>
    <child link="left_wheel_a_link"/>
    <origin rpy="0 0 0" xyz="0.06944 -0.43769 0.00157"/>
    <axis xyz="1 0 0"/>
    <mimic joint="left_mutator_joint" multiplier="1" offset="0"/>
    <limit effort="10000" velocity="1000"/>
    <joint_properties damping="1.0" friction="1.0"/>
  </joint>
  <link name="left_wheel_b_link">
    <!-- Adding visual and collision elements -->
    <visual>
      <geometry>
        <mesh filename="package://mbs_rovo_gazebo/robot_gazebo_description/meshes/visual/rare_wheel.dae"/>
      </geometry>
      <origin rpy="0 0 0" xyz="0 0 0"/>
    </visual>
    <collision>
      <geometry>
        <mesh filename="package://mbs_rovo_gazebo/robot_gazebo_description/meshes/collision/rare_wheel.stl"/>
      </geometry>
      <origin rpy="0 0 0" xyz="0 0 0"/>
    </collision>
    <inertial>
      <mass value="0.5"/>
      <inertia ixx="0.00094" ixy="0.0" ixz="-0.0" iyy="0.00052" iyz="-0.0" izz="0.00052"/>
    </inertial>
  </link>
  <joint name="left_wheel_b_joint" type="continuous">
    <parent link="left_axle_link"/>
    <child link="left_wheel_b_link"/>
    <origin rpy="0 0 0" xyz="0.06922 -0.24269 -0.04742"/>
    <axis xyz="1 0 0"/>
    <mimic joint="left_mutator_joint" multiplier="1" offset="0"/>
    <limit effort="10000" velocity="1000"/>
    <joint_properties damping="1.0" friction="1.0"/>
  </joint>
  <link name="left_wheel_c_link">
    <!-- Adding visual and collision elements -->
    <visual>
      <geometry>
        <mesh filename="package://mbs_rovo_gazebo/robot_gazebo_description/meshes/visual/rare_wheel.dae"/>
      </geometry>
      <origin rpy="0 0 0" xyz="0 0 0"/>
    </visual>
    <collision>
      <geometry>
        <mesh filename="package://mbs_rovo_gazebo/robot_gazebo_description/meshes/collision/rare_wheel.stl"/>
      </geometry>
      <origin rpy="0 0 0" xyz="0 0 0"/>
    </collision>
    <inertial>
      <mass value="0.5"/>
      <inertia ixx="0.00094" ixy="0.0" ixz="-0.0" iyy="0.00052" iyz="-0.0" izz="0.00052"/>
    </inertial>
  </link>
  <joint name="left_wheel_c_joint" type="continuous">
    <parent link="left_axle_link"/>
    <child link="left_wheel_c_link"/>
    <origin rpy="0 0 0" xyz="0.06923 -0.08468 -0.04742"/>
    <axis xyz="1 0 0"/>
    <mimic joint="left_mutator_joint" multiplier="1" offset="0"/>
    <limit effort="10000" velocity="1000"/>
    <joint_properties damping="1.0" friction="1.0"/>
  </joint>
  <link name="left_wheel_d_link">
    <!-- Adding visual and collision elements -->
    <visual>
      <geometry>
        <mesh filename="package://mbs_rovo_gazebo/robot_gazebo_description/meshes/visual/rare_wheel.dae"/>
      </geometry>
      <origin rpy="0 0 0" xyz="0 0 0"/>
    </visual>
    <collision>
      <geometry>
        <mesh filename="package://mbs_rovo_gazebo/robot_gazebo_description/meshes/collision/rare_wheel.stl"/>
      </geometry>
      <origin rpy="0 0 0" xyz="0 0 0"/>
    </collision>
    <inertial>
      <mass value="0.5"/>
      <inertia ixx="0.00094" ixy="0.0" ixz="-0.0" iyy="0.00052" iyz="-0.0" izz="0.00052"/>
    </inertial>
  </link>
  <joint name="left_wheel_d_joint" type="continuous">
    <parent link="left_axle_link"/>
    <child link="left_wheel_d_link"/>
    <origin rpy="0 0 0" xyz="0.06923 0.07333 -0.04743"/>
    <axis xyz="1 0 0"/>
    <mimic joint="left_mutator_joint" multiplier="1" offset="0"/>
    <limit effort="10000" velocity="1000"/>
    <joint_properties damping="1.0" friction="1.0"/>
  </joint>
  <link name="left_wheel_e_link">
    <!-- Adding visual and collision elements -->
    <visual>
      <geometry>
        <mesh filename="package://mbs_rovo_gazebo/robot_gazebo_description/meshes/visual/rare_wheel.dae"/>
      </geometry>
      <origin rpy="0 0 0" xyz="0 0 0"/>
    </visual>
    <collision>
      <geometry>
        <mesh filename="package://mbs_rovo_gazebo/robot_gazebo_description/meshes/collision/rare_wheel.stl"/>
      </geometry>
      <origin rpy="0 0 0" xyz="0 0 0"/>
    </collision>
    <inertial>
      <mass value="0.5"/>
      <inertia ixx="0.00094" ixy="0.0" ixz="-0.0" iyy="0.00052" iyz="-0.0" izz="0.00052"/>
    </inertial>
  </link>
  <joint name="left_wheel_e_joint" type="continuous">
    <parent link="left_axle_link"/>
    <child link="left_wheel_e_link"/>
    <origin rpy="0 0 0" xyz="0.06923 0.23132 -0.04744"/>
    <axis xyz="1 0 0"/>
    <mimic joint="left_mutator_joint" multiplier="1" offset="0"/>
    <limit effort="10000" velocity="1000"/>
    <joint_properties damping="1.0" friction="1.0"/>
  </joint>
  <link name="left_wheel_f_link">
    <!-- Adding visual and collision elements -->
    <visual>
      <geometry>
        <mesh filename="package://mbs_rovo_gazebo/robot_gazebo_description/meshes/visual/rare_wheel.dae"/>
      </geometry>
      <origin rpy="0 0 0" xyz="0 0 0"/>
    </visual>
    <collision>
      <geometry>
        <mesh filename="package://mbs_rovo_gazebo/robot_gazebo_description/meshes/collision/rare_wheel.stl"/>
      </geometry>
      <origin rpy="0 0 0" xyz="0 0 0"/>
    </collision>
    <inertial>
      <mass value="0.5"/>
      <inertia ixx="0.00094" ixy="0.0" ixz="-0.0" iyy="0.00052" iyz="-0.0" izz="0.00052"/>
    </inertial>
  </link>
  <joint name="left_wheel_f_joint" type="continuous">
    <parent link="left_axle_link"/>
    <child link="left_wheel_f_link"/>
    <origin rpy="0 0 0" xyz="0.06915 0.45123 -0.03694"/>
    <axis xyz="1 0 0"/>
    <mimic joint="left_mutator_joint" multiplier="1" offset="0"/>
    <limit effort="10000" velocity="1000"/>
    <joint_properties damping="1.0" friction="1.0"/>
  </joint>
  <link name="left_wheel_g_link">
    <!-- Adding visual and collision elements -->
    <visual>
      <geometry>
        <mesh filename="package://mbs_rovo_gazebo/robot_gazebo_description/meshes/visual/front_wheel.dae"/>
      </geometry>
      <origin rpy="0 3.14156 0" xyz="0 0 0"/>
    </visual>
    <collision>
      <geometry>
        <mesh filename="package://mbs_rovo_gazebo/robot_gazebo_description/meshes/collision/front_wheel.stl"/>
      </geometry>
      <origin rpy="0 3.14156 0" xyz="0 0 0"/>
    </collision>
    <inertial>
      <mass value="1.0"/>
      <inertia ixx="0.00458" ixy="0.00001" ixz="-0.0" iyy="0.00239" iyz="-0.0" izz="0.00239"/>
    </inertial>
  </link>
  <joint name="left_wheel_g_joint" type="continuous">
    <parent link="left_axle_link"/>
    <child link="left_wheel_g_link"/>
    <origin rpy="0 0 0" xyz="-0.07296 -0.43768 0.00156"/>
    <axis xyz="1 0 0"/>
    <mimic joint="left_mutator_joint" multiplier="1" offset="0"/>
    <limit effort="10000" velocity="1000"/>
    <joint_properties damping="1.0" friction="1.0"/>
  </joint>
  <link name="left_wheel_h_link">
    <!-- Adding visual and collision elements -->
    <visual>
      <geometry>
        <mesh filename="package://mbs_rovo_gazebo/robot_gazebo_description/meshes/visual/rare_wheel.dae"/>
      </geometry>
      <origin rpy="0 3.14156 0" xyz="0 0 0"/>
    </visual>
    <collision>
      <geometry>
        <mesh filename="package://mbs_rovo_gazebo/robot_gazebo_description/meshes/collision/rare_wheel.stl"/>
      </geometry>
      <origin rpy="0 3.14156 0" xyz="0 0 0"/>
    </collision>
    <inertial>
      <mass value="0.5"/>
      <inertia ixx="0.00094" ixy="0.0" ixz="-0.0" iyy="0.00052" iyz="-0.0" izz="0.00052"/>
    </inertial>
  </link>
  <joint name="left_wheel_h_joint" type="continuous">
    <parent link="left_axle_link"/>
    <child link="left_wheel_h_link"/>
    <origin rpy="0 0 0" xyz="-0.07275 -0.24269 -0.04742"/>
    <axis xyz="1 0 0"/>
    <mimic joint="left_mutator_joint" multiplier="1" offset="0"/>
    <limit effort="10000" velocity="1000"/>
    <joint_properties damping="1.0" friction="1.0"/>
  </joint>
  <link name="left_wheel_i_link">
    <!-- Adding visual and collision elements -->
    <visual>
      <geometry>
        <mesh filename="package://mbs_rovo_gazebo/robot_gazebo_description/meshes/visual/rare_wheel.dae"/>
      </geometry>
      <origin rpy="0 3.14156 0" xyz="0 0 0"/>
    </visual>
    <collision>
      <geometry>
        <mesh filename="package://mbs_rovo_gazebo/robot_gazebo_description/meshes/collision/rare_wheel.stl"/>
      </geometry>
      <origin rpy="0 3.14156 0" xyz="0 0 0"/>
    </collision>
    <inertial>
      <mass value="0.5"/>
      <inertia ixx="0.00094" ixy="0.0" ixz="-0.0" iyy="0.00052" iyz="-0.0" izz="0.00052"/>
    </inertial>
  </link>
  <joint name="left_wheel_i_joint" type="continuous">
    <parent link="left_axle_link"/>
    <child link="left_wheel_i_link"/>
    <origin rpy="0 0 0" xyz="-0.07274 -0.08468 -0.04742"/>
    <axis xyz="1 0 0"/>
    <mimic joint="left_mutator_joint" multiplier="1" offset="0"/>
    <limit effort="10000" velocity="1000"/>
    <joint_properties damping="1.0" friction="1.0"/>
  </joint>
  <link name="left_wheel_j_link">
    <!-- Adding visual and collision elements -->
    <visual>
      <geometry>
        <mesh filename="package://mbs_rovo_gazebo/robot_gazebo_description/meshes/visual/rare_wheel.dae"/>
      </geometry>
      <origin rpy="0 3.14156 0" xyz="0 0 0"/>
    </visual>
    <collision>
      <geometry>
        <mesh filename="package://mbs_rovo_gazebo/robot_gazebo_description/meshes/collision/rare_wheel.stl"/>
      </geometry>
      <origin rpy="0 3.14156 0" xyz="0 0 0"/>
    </collision>
    <inertial>
      <mass value="0.5"/>
      <inertia ixx="0.00094" ixy="0.0" ixz="-0.0" iyy="0.00052" iyz="-0.0" izz="0.00052"/>
    </inertial>
  </link>
  <joint name="left_wheel_j_joint" type="continuous">
    <parent link="left_axle_link"/>
    <child link="left_wheel_j_link"/>
    <origin rpy="0 0 0" xyz="-0.07274 0.07333 -0.04743"/>
    <axis xyz="1 0 0"/>
    <mimic joint="left_mutator_joint" multiplier="1" offset="0"/>
    <limit effort="10000" velocity="1000"/>
    <joint_properties damping="1.0" friction="1.0"/>
  </joint>
  <link name="left_wheel_k_link">
    <!-- Adding visual and collision elements -->
    <visual>
      <geometry>
        <mesh filename="package://mbs_rovo_gazebo/robot_gazebo_description/meshes/visual/rare_wheel.dae"/>
      </geometry>
      <origin rpy="0 3.14156 0" xyz="0 0 0"/>
    </visual>
    <collision>
      <geometry>
        <mesh filename="package://mbs_rovo_gazebo/robot_gazebo_description/meshes/collision/rare_wheel.stl"/>
      </geometry>
      <origin rpy="0 3.14156 0" xyz="0 0 0"/>
    </collision>
    <inertial>
      <mass value="0.5"/>
      <inertia ixx="0.00094" ixy="0.0" ixz="-0.0" iyy="0.00052" iyz="-0.0" izz="0.00052"/>
    </inertial>
  </link>
  <joint name="left_wheel_k_joint" type="continuous">
    <parent link="left_axle_link"/>
    <child link="left_wheel_k_link"/>
    <origin rpy="0 0 0" xyz="-0.07274 0.23132 -0.04744"/>
    <axis xyz="1 0 0"/>
    <mimic joint="left_mutator_joint" multiplier="1" offset="0"/>
    <limit effort="10000" velocity="1000"/>
    <joint_properties damping="1.0" friction="1.0"/>
  </joint>
  <link name="left_wheel_l_link">
    <!-- Adding visual and collision elements -->
    <visual>
      <geometry>
        <mesh filename="package://mbs_rovo_gazebo/robot_gazebo_description/meshes/visual/rare_wheel.dae"/>
      </geometry>
      <origin rpy="0 3.14156 0" xyz="0 0 0"/>
    </visual>
    <collision>
      <geometry>
        <mesh filename="package://mbs_rovo_gazebo/robot_gazebo_description/meshes/collision/rare_wheel.stl"/>
      </geometry>
      <origin rpy="0 3.14156 0" xyz="0 0 0"/>
    </collision>
    <inertial>
      <mass value="0.5"/>
      <inertia ixx="0.00094" ixy="0.0" ixz="-0.0" iyy="0.00052" iyz="-0.0" izz="0.00052"/>
    </inertial>
  </link>
  <joint name="left_wheel_l_joint" type="continuous">
    <parent link="left_axle_link"/>
    <child link="left_wheel_l_link"/>
    <origin rpy="0 0 0" xyz="-0.07267 0.4512 -0.03695"/>
    <axis xyz="1 0 0"/>
    <mimic joint="left_mutator_joint" multiplier="1" offset="0"/>
    <limit effort="10000" velocity="1000"/>
    <joint_properties damping="1.0" friction="1.0"/>
  </joint>
  <gazebo>
    <plugin filename="libgazebo_ros_control.so" name="gazebo_ros_control">
      <robotNamespace>/</robotNamespace>
      <robotSimType>gazebo_ros_control/DefaultRobotHWSim</robotSimType>
    </plugin>
  </gazebo>
  <gazebo reference="base_link">
    <turnGravityOff>false</turnGravityOff>
  </gazebo>
  <transmission name="right_mutator_joint_transmission">
    <type>transmission_interface/SimpleTransmission</type>
    <joint name="right_mutator_joint">
      <hardwareInterface>hardware_interface/VelocityJointInterface</hardwareInterface>
    </joint>
    <actuator name="right_mutator_joint_motor">
      <hardwareInterface>hardware_interface/VelocityJointInterface</hardwareInterface>
      <mechanicalReduction>1</mechanicalReduction>
    </actuator>
  </transmission>
  <transmission name="right_wheel_a_joint_transmission">
    <type>transmission_interface/SimpleTransmission</type>
    <joint name="right_wheel_a_joint">
      <hardwareInterface>hardware_interface/VelocityJointInterface</hardwareInterface>
    </joint>
    <actuator name="right_wheel_a_joint_motor">
      <hardwareInterface>hardware_interface/VelocityJointInterface</hardwareInterface>
      <mechanicalReduction>1</mechanicalReduction>
    </actuator>
  </transmission>
  <transmission name="right_wheel_b_joint_transmission">
    <type>transmission_interface/SimpleTransmission</type>
    <joint name="right_wheel_b_joint">
      <hardwareInterface>hardware_interface/VelocityJointInterface</hardwareInterface>
    </joint>
    <actuator name="right_wheel_b_joint_motor">
      <hardwareInterface>hardware_interface/VelocityJointInterface</hardwareInterface>
      <mechanicalReduction>1</mechanicalReduction>
    </actuator>
  </transmission>
  <transmission name="right_wheel_c_joint_transmission">
    <type>transmission_interface/SimpleTransmission</type>
    <joint name="right_wheel_c_joint">
      <hardwareInterface>hardware_interface/VelocityJointInterface</hardwareInterface>
    </joint>
    <actuator name="right_wheel_c_joint_motor">
      <hardwareInterface>hardware_interface/VelocityJointInterface</hardwareInterface>
      <mechanicalReduction>1</mechanicalReduction>
    </actuator>
  </transmission>
  <transmission name="right_wheel_d_joint_transmission">
    <type>transmission_interface/SimpleTransmission</type>
    <joint name="right_wheel_d_joint">
      <hardwareInterface>hardware_interface/VelocityJointInterface</hardwareInterface>
    </joint>
    <actuator name="right_wheel_d_joint_motor">
      <hardwareInterface>hardware_interface/VelocityJointInterface</hardwareInterface>
      <mechanicalReduction>1</mechanicalReduction>
    </actuator>
  </transmission>
  <transmission name="right_wheel_e_joint_transmission">
    <type>transmission_interface/SimpleTransmission</type>
    <joint name="right_wheel_e_joint">
      <hardwareInterface>hardware_interface/VelocityJointInterface</hardwareInterface>
    </joint>
    <actuator name="right_wheel_e_joint_motor">
      <hardwareInterface>hardware_interface/VelocityJointInterface</hardwareInterface>
      <mechanicalReduction>1</mechanicalReduction>
    </actuator>
  </transmission>
  <transmission name="right_wheel_f_joint_transmission">
    <type>transmission_interface/SimpleTransmission</type>
    <joint name="right_wheel_f_joint">
      <hardwareInterface>hardware_interface/VelocityJointInterface</hardwareInterface>
    </joint>
    <actuator name="right_wheel_f_joint_motor">
      <hardwareInterface>hardware_interface/VelocityJointInterface</hardwareInterface>
      <mechanicalReduction>1</mechanicalReduction>
    </actuator>
  </transmission>
  <transmission name="right_wheel_g_joint_transmission">
    <type>transmission_interface/SimpleTransmission</type>
    <joint name="right_wheel_g_joint">
      <hardwareInterface>hardware_interface/VelocityJointInterface</hardwareInterface>
    </joint>
    <actuator name="right_wheel_g_joint_motor">
      <hardwareInterface>hardware_interface/VelocityJointInterface</hardwareInterface>
      <mechanicalReduction>1</mechanicalReduction>
    </actuator>
  </transmission>
  <transmission name="right_wheel_h_joint_transmission">
    <type>transmission_interface/SimpleTransmission</type>
    <joint name="right_wheel_h_joint">
      <hardwareInterface>hardware_interface/VelocityJointInterface</hardwareInterface>
    </joint>
    <actuator name="right_wheel_h_joint_motor">
      <hardwareInterface>hardware_interface/VelocityJointInterface</hardwareInterface>
      <mechanicalReduction>1</mechanicalReduction>
    </actuator>
  </transmission>
  <transmission name="right_wheel_i_joint_transmission">
    <type>transmission_interface/SimpleTransmission</type>
    <joint name="right_wheel_i_joint">
      <hardwareInterface>hardware_interface/VelocityJointInterface</hardwareInterface>
    </joint>
    <actuator name="right_wheel_i_joint_motor">
      <hardwareInterface>hardware_interface/VelocityJointInterface</hardwareInterface>
      <mechanicalReduction>1</mechanicalReduction>
    </actuator>
  </transmission>
  <transmission name="right_wheel_j_joint_transmission">
    <type>transmission_interface/SimpleTransmission</type>
    <joint name="right_wheel_j_joint">
      <hardwareInterface>hardware_interface/VelocityJointInterface</hardwareInterface>
    </joint>
    <actuator name="right_wheel_j_joint_motor">
      <hardwareInterface>hardware_interface/VelocityJointInterface</hardwareInterface>
      <mechanicalReduction>1</mechanicalReduction>
    </actuator>
  </transmission>
  <transmission name="right_wheel_k_joint_transmission">
    <type>transmission_interface/SimpleTransmission</type>
    <joint name="right_wheel_k_joint">
      <hardwareInterface>hardware_interface/VelocityJointInterface</hardwareInterface>
    </joint>
    <actuator name="right_wheel_k_joint_motor">
      <hardwareInterface>hardware_interface/VelocityJointInterface</hardwareInterface>
      <mechanicalReduction>1</mechanicalReduction>
    </actuator>
  </transmission>
  <transmission name="right_wheel_l_joint_transmission">
    <type>transmission_interface/SimpleTransmission</type>
    <joint name="right_wheel_l_joint">
      <hardwareInterface>hardware_interface/VelocityJointInterface</hardwareInterface>
    </joint>
    <actuator name="right_wheel_l_joint_motor">
      <hardwareInterface>hardware_interface/VelocityJointInterface</hardwareInterface>
      <mechanicalReduction>1</mechanicalReduction>
    </actuator>
  </transmission>
  <transmission name="left_mutator_joint_transmission">
    <type>transmission_interface/SimpleTransmission</type>
    <joint name="left_mutator_joint">
      <hardwareInterface>hardware_interface/VelocityJointInterface</hardwareInterface>
    </joint>
    <actuator name="left_mutator_joint_motor">
      <hardwareInterface>hardware_interface/VelocityJointInterface</hardwareInterface>
      <mechanicalReduction>1</mechanicalReduction>
    </actuator>
  </transmission>
  <transmission name="left_wheel_a_joint_transmission">
    <type>transmission_interface/SimpleTransmission</type>
    <joint name="left_wheel_a_joint">
      <hardwareInterface>hardware_interface/VelocityJointInterface</hardwareInterface>
    </joint>
    <actuator name="left_wheel_a_joint_motor">
      <hardwareInterface>hardware_interface/VelocityJointInterface</hardwareInterface>
      <mechanicalReduction>1</mechanicalReduction>
    </actuator>
  </transmission>
  <transmission name="left_wheel_b_joint_transmission">
    <type>transmission_interface/SimpleTransmission</type>
    <joint name="left_wheel_b_joint">
      <hardwareInterface>hardware_interface/VelocityJointInterface</hardwareInterface>
    </joint>
    <actuator name="left_wheel_b_joint_motor">
      <hardwareInterface>hardware_interface/VelocityJointInterface</hardwareInterface>
      <mechanicalReduction>1</mechanicalReduction>
    </actuator>
  </transmission>
  <transmission name="left_wheel_c_joint_transmission">
    <type>transmission_interface/SimpleTransmission</type>
    <joint name="left_wheel_c_joint">
      <hardwareInterface>hardware_interface/VelocityJointInterface</hardwareInterface>
    </joint>
    <actuator name="left_wheel_c_joint_motor">
      <hardwareInterface>hardware_interface/VelocityJointInterface</hardwareInterface>
      <mechanicalReduction>1</mechanicalReduction>
    </actuator>
  </transmission>
  <transmission name="left_wheel_d_joint_transmission">
    <type>transmission_interface/SimpleTransmission</type>
    <joint name="left_wheel_d_joint">
      <hardwareInterface>hardware_interface/VelocityJointInterface</hardwareInterface>
    </joint>
    <actuator name="left_wheel_d_joint_motor">
      <hardwareInterface>hardware_interface/VelocityJointInterface</hardwareInterface>
      <mechanicalReduction>1</mechanicalReduction>
    </actuator>
  </transmission>
  <transmission name="left_wheel_e_joint_transmission">
    <type>transmission_interface/SimpleTransmission</type>
    <joint name="left_wheel_e_joint">
      <hardwareInterface>hardware_interface/VelocityJointInterface</hardwareInterface>
    </joint>
    <actuator name="left_wheel_e_joint_motor">
      <hardwareInterface>hardware_interface/VelocityJointInterface</hardwareInterface>
      <mechanicalReduction>1</mechanicalReduction>
    </actuator>
  </transmission>
  <transmission name="left_wheel_f_joint_transmission">
    <type>transmission_interface/SimpleTransmission</type>
    <joint name="left_wheel_f_joint">
      <hardwareInterface>hardware_interface/VelocityJointInterface</hardwareInterface>
    </joint>
    <actuator name="left_wheel_f_joint_motor">
      <hardwareInterface>hardware_interface/VelocityJointInterface</hardwareInterface>
      <mechanicalReduction>1</mechanicalReduction>
    </actuator>
  </transmission>
  <transmission name="left_wheel_g_joint_transmission">
    <type>transmission_interface/SimpleTransmission</type>
    <joint name="left_wheel_g_joint">
      <hardwareInterface>hardware_interface/VelocityJointInterface</hardwareInterface>
    </joint>
    <actuator name="left_wheel_g_joint_motor">
      <hardwareInterface>hardware_interface/VelocityJointInterface</hardwareInterface>
      <mechanicalReduction>1</mechanicalReduction>
    </actuator>
  </transmission>
  <transmission name="left_wheel_h_joint_transmission">
    <type>transmission_interface/SimpleTransmission</type>
    <joint name="left_wheel_h_joint">
      <hardwareInterface>hardware_interface/VelocityJointInterface</hardwareInterface>
    </joint>
    <actuator name="left_wheel_h_joint_motor">
      <hardwareInterface>hardware_interface/VelocityJointInterface</hardwareInterface>
      <mechanicalReduction>1</mechanicalReduction>
    </actuator>
  </transmission>
  <transmission name="left_wheel_i_joint_transmission">
    <type>transmission_interface/SimpleTransmission</type>
    <joint name="left_wheel_i_joint">
      <hardwareInterface>hardware_interface/VelocityJointInterface</hardwareInterface>
    </joint>
    <actuator name="left_wheel_i_joint_motor">
      <hardwareInterface>hardware_interface/VelocityJointInterface</hardwareInterface>
      <mechanicalReduction>1</mechanicalReduction>
    </actuator>
  </transmission>
  <transmission name="left_wheel_j_joint_transmission">
    <type>transmission_interface/SimpleTransmission</type>
    <joint name="left_wheel_j_joint">
      <hardwareInterface>hardware_interface/VelocityJointInterface</hardwareInterface>
    </joint>
    <actuator name="left_wheel_j_joint_motor">
      <hardwareInterface>hardware_interface/VelocityJointInterface</hardwareInterface>
      <mechanicalReduction>1</mechanicalReduction>
    </actuator>
  </transmission>
  <transmission name="left_wheel_k_joint_transmission">
    <type>transmission_interface/SimpleTransmission</type>
    <joint name="left_wheel_k_joint">
      <hardwareInterface>hardware_interface/VelocityJointInterface</hardwareInterface>
    </joint>
    <actuator name="left_wheel_k_joint_motor">
      <hardwareInterface>hardware_interface/VelocityJointInterface</hardwareInterface>
      <mechanicalReduction>1</mechanicalReduction>
    </actuator>
  </transmission>
  <transmission name="left_wheel_l_joint_transmission">
    <type>transmission_interface/SimpleTransmission</type>
    <joint name="left_wheel_l_joint">
      <hardwareInterface>hardware_interface/VelocityJointInterface</hardwareInterface>
    </joint>
    <actuator name="left_wheel_l_joint_motor">
      <hardwareInterface>hardware_interface/VelocityJointInterface</hardwareInterface>
      <mechanicalReduction>1</mechanicalReduction>
    </actuator>
  </transmission>
  <transmission name="left_wheel_va_joint_transmission">
    <type>transmission_interface/SimpleTransmission</type>
    <joint name="left_wheel_va_joint">
      <hardwareInterface>hardware_interface/VelocityJointInterface</hardwareInterface>
    </joint>
    <actuator name="left_wheel_va_joint_motor">
      <hardwareInterface>hardware_interface/VelocityJointInterface</hardwareInterface>
      <mechanicalReduction>1</mechanicalReduction>
    </actuator>
  </transmission>
  <transmission name="left_wheel_vb_joint_transmission">
    <type>transmission_interface/SimpleTransmission</type>
    <joint name="left_wheel_vb_joint">
      <hardwareInterface>hardware_interface/VelocityJointInterface</hardwareInterface>
    </joint>
    <actuator name="left_wheel_vb_joint_motor">
      <hardwareInterface>hardware_interface/VelocityJointInterface</hardwareInterface>
      <mechanicalReduction>1</mechanicalReduction>
    </actuator>
  </transmission>
  <transmission name="left_wheel_vc_joint_transmission">
    <type>transmission_interface/SimpleTransmission</type>
    <joint name="left_wheel_vc_joint">
      <hardwareInterface>hardware_interface/VelocityJointInterface</hardwareInterface>
    </joint>
    <actuator name="left_wheel_vc_joint_motor">
      <hardwareInterface>hardware_interface/VelocityJointInterface</hardwareInterface>
      <mechanicalReduction>1</mechanicalReduction>
    </actuator>
  </transmission>
  <transmission name="left_wheel_vd_joint_transmission">
    <type>transmission_interface/SimpleTransmission</type>
    <joint name="left_wheel_vd_joint">
      <hardwareInterface>hardware_interface/VelocityJointInterface</hardwareInterface>
    </joint>
    <actuator name="left_wheel_vd_joint_motor">
      <hardwareInterface>hardware_interface/VelocityJointInterface</hardwareInterface>
      <mechanicalReduction>1</mechanicalReduction>
    </actuator>
  </transmission>
  <transmission name="left_wheel_ve_joint_transmission">
    <type>transmission_interface/SimpleTransmission</type>
    <joint name="left_wheel_ve_joint">
      <hardwareInterface>hardware_interface/VelocityJointInterface</hardwareInterface>
    </joint>
    <actuator name="left_wheel_ve_joint_motor">
      <hardwareInterface>hardware_interface/VelocityJointInterface</hardwareInterface>
      <mechanicalReduction>1</mechanicalReduction>
    </actuator>
  </transmission>
  <transmission name="left_wheel_vf_joint_transmission">
    <type>transmission_interface/SimpleTransmission</type>
    <joint name="left_wheel_vf_joint">
      <hardwareInterface>hardware_interface/VelocityJointInterface</hardwareInterface>
    </joint>
    <actuator name="left_wheel_vf_joint_motor">
      <hardwareInterface>hardware_interface/VelocityJointInterface</hardwareInterface>
      <mechanicalReduction>1</mechanicalReduction>
    </actuator>
  </transmission>
  <transmission name="left_wheel_vg_joint_transmission">
    <type>transmission_interface/SimpleTransmission</type>
    <joint name="left_wheel_vg_joint">
      <hardwareInterface>hardware_interface/VelocityJointInterface</hardwareInterface>
    </joint>
    <actuator name="left_wheel_vg_joint_motor">
      <hardwareInterface>hardware_interface/VelocityJointInterface</hardwareInterface>
      <mechanicalReduction>1</mechanicalReduction>
    </actuator>
  </transmission>
  <transmission name="left_wheel_vh_joint_transmission">
    <type>transmission_interface/SimpleTransmission</type>
    <joint name="left_wheel_vh_joint">
      <hardwareInterface>hardware_interface/VelocityJointInterface</hardwareInterface>
    </joint>
    <actuator name="left_wheel_vh_joint_motor">
      <hardwareInterface>hardware_interface/VelocityJointInterface</hardwareInterface>
      <mechanicalReduction>1</mechanicalReduction>
    </actuator>
  </transmission>
  <transmission name="right_wheel_va_joint_transmission">
    <type>transmission_interface/SimpleTransmission</type>
    <joint name="right_wheel_va_joint">
      <hardwareInterface>hardware_interface/VelocityJointInterface</hardwareInterface>
    </joint>
    <actuator name="right_wheel_va_joint_motor">
      <hardwareInterface>hardware_interface/VelocityJointInterface</hardwareInterface>
      <mechanicalReduction>1</mechanicalReduction>
    </actuator>
  </transmission>
  <transmission name="right_wheel_vb_joint_transmission">
    <type>transmission_interface/SimpleTransmission</type>
    <joint name="right_wheel_vb_joint">
      <hardwareInterface>hardware_interface/VelocityJointInterface</hardwareInterface>
    </joint>
    <actuator name="right_wheel_vb_joint_motor">
      <hardwareInterface>hardware_interface/VelocityJointInterface</hardwareInterface>
      <mechanicalReduction>1</mechanicalReduction>
    </actuator>
  </transmission>
  <transmission name="right_wheel_vc_joint_transmission">
    <type>transmission_interface/SimpleTransmission</type>
    <joint name="right_wheel_vc_joint">
      <hardwareInterface>hardware_interface/VelocityJointInterface</hardwareInterface>
    </joint>
    <actuator name="right_wheel_vc_joint_motor">
      <hardwareInterface>hardware_interface/VelocityJointInterface</hardwareInterface>
      <mechanicalReduction>1</mechanicalReduction>
    </actuator>
  </transmission>
  <transmission name="right_wheel_vd_joint_transmission">
    <type>transmission_interface/SimpleTransmission</type>
    <joint name="right_wheel_vd_joint">
      <hardwareInterface>hardware_interface/VelocityJointInterface</hardwareInterface>
    </joint>
    <actuator name="right_wheel_vd_joint_motor">
      <hardwareInterface>hardware_interface/VelocityJointInterface</hardwareInterface>
      <mechanicalReduction>1</mechanicalReduction>
    </actuator>
  </transmission>
  <transmission name="right_wheel_ve_joint_transmission">
    <type>transmission_interface/SimpleTransmission</type>
    <joint name="right_wheel_ve_joint">
      <hardwareInterface>hardware_interface/VelocityJointInterface</hardwareInterface>
    </joint>
    <actuator name="right_wheel_ve_joint_motor">
      <hardwareInterface>hardware_interface/VelocityJointInterface</hardwareInterface>
      <mechanicalReduction>1</mechanicalReduction>
    </actuator>
  </transmission>
  <transmission name="right_wheel_vf_joint_transmission">
    <type>transmission_interface/SimpleTransmission</type>
    <joint name="right_wheel_vf_joint">
      <hardwareInterface>hardware_interface/VelocityJointInterface</hardwareInterface>
    </joint>
    <actuator name="right_wheel_vf_joint_motor">
      <hardwareInterface>hardware_interface/VelocityJointInterface</hardwareInterface>
      <mechanicalReduction>1</mechanicalReduction>
    </actuator>
  </transmission>
  <transmission name="right_wheel_vg_joint_transmission">
    <type>transmission_interface/SimpleTransmission</type>
    <joint name="right_wheel_vg_joint">
      <hardwareInterface>hardware_interface/VelocityJointInterface</hardwareInterface>
    </joint>
    <actuator name="right_wheel_vg_joint_motor">
      <hardwareInterface>hardware_interface/VelocityJointInterface</hardwareInterface>
      <mechanicalReduction>1</mechanicalReduction>
    </actuator>
  </transmission>
  <transmission name="right_wheel_vh_joint_transmission">
    <type>transmission_interface/SimpleTransmission</type>
    <joint name="right_wheel_vh_joint">
      <hardwareInterface>hardware_interface/VelocityJointInterface</hardwareInterface>
    </joint>
    <actuator name="right_wheel_vh_joint_motor">
      <hardwareInterface>hardware_interface/VelocityJointInterface</hardwareInterface>
      <mechanicalReduction>1</mechanicalReduction>
    </actuator>
  </transmission>
 
  <!-- Ouster Augment -->
  <link name="os1_sensor">
      <inertial>
         <mass value="0.33"/>
         <origin xyz="0 0 0.0365" rpy="0 0 0" />
         <inertia ixx="0.000241148" ixy="0" ixz="0" iyy="0.000241148" iyz="0" izz="0.000264"/>
      </inertial>
      <collision>
         <origin xyz="0 0 0" rpy="0 0 0" /> <!-- z = 0.0365 -->
         <geometry>
 	        <cylinder radius="0.04" length="0.073"/>
         </geometry>
      </collision>
      <visual>
         <origin xyz="0 0 0.0" rpy="0 0 1.5707" />
         <geometry>
	         <mesh filename="package://ouster_description/meshes/os1_64.dae" /> 
         </geometry>
      </visual>
  </link>

  <joint name="os1_sensor_joint" type="fixed">
      <parent link="chasis_link" />
      <child link="os1_sensor" />
      <origin xyz="0.0 0.0 0.32" rpy="0 0 0" /> <!-- 0.03618 is the default height -->
  </joint>

  <!-- Ouster gazebo library -->
  <gazebo reference="os1_sensor">
        <sensor type="ray" name="os1_sensor-OS1-64">
          <pose>0 0 0 0 0 0</pose>
          <visualize>false</visualize>
          <update_rate>10</update_rate>
          <ray>
            <scan>
              <horizontal>
                <samples>220</samples> 
                <resolution>1</resolution>
                <min_angle>-3.1415926535897931</min_angle>
                <max_angle>3.1415926535897931</max_angle>
              </horizontal>
              <vertical>
                <samples>64</samples>
                <resolution>1</resolution>
                <min_angle>-0.26</min_angle>
                <max_angle>0.26</max_angle>
              </vertical>
            </scan>
            <range>
              <min>0.90</min>
              <max>75.0</max>
              <resolution>0.03</resolution>
            </range>
          </ray>
          <plugin name="gazebo_ros_laser_controller" filename="libgazebo_ros_ouster_laser.so">
            <topicName>/points</topicName>
            <frameName>os1_sensor</frameName>
            <min_range>0.90</min_range>
            <max_range>75.0</max_range>
            <gaussianNoise>0.008</gaussianNoise>
          </plugin>
        </sensor>
    </gazebo> 
</robot>