<sdf version='1.7'>
  <model name='b1_description'>
    <link name='base'>
      <inertial>
        <pose>0.008464 0.004045 -0.000763 0 -0 0</pose>
        <mass>9.042</mass>
        <inertia>
          <ixx>0.0333602</ixx>
          <ixy>-0.000451662</ixy>
          <ixz>0.000487609</ixz>
          <iyy>0.161173</iyy>
          <iyz>4.83591e-05</iyz>
          <izz>0.174705</izz>
        </inertia>
      </inertial>
      <collision name='base_fixed_joint_lump__trunk_collision'>
        <pose>0 0 0 0 -0 0</pose>
        <geometry>
          <box>
            <size>0.647 0.3 0.15</size>
          </box>
        </geometry>
        <surface>
          <contact>
            <ode>
              <kp>1e+06</kp>
              <kd>1</kd>
            </ode>
          </contact>
          <friction>
            <ode>
              <mu>0.2</mu>
              <mu2>0.2</mu2>
            </ode>
          </friction>
        </surface>
      </collision>
      <collision name='base_fixed_joint_lump__imu_link_collision_1'>
        <pose>0 0 0 0 -0 0</pose>
        <geometry>
          <box>
            <size>0.001 0.001 0.001</size>
          </box>
        </geometry>
        <surface>
          <contact>
            <ode/>
          </contact>
          <friction>
            <ode>
              <mu>0.2</mu>
              <mu2>0.2</mu2>
            </ode>
          </friction>
        </surface>
      </collision>
      <collision name='base_fixed_joint_lump__sim_collider_collision_2'>
        <pose>0 0 0 0 -0 0</pose>
        <geometry>
          <box>
            <size>0.65 0.45 0.1</size>
          </box>
        </geometry>
        <surface>
          <contact>
            <ode/>
          </contact>
          <friction>
            <ode/>
          </friction>
        </surface>
      </collision>
      <visual name='base_visual'>
        <pose>0 0 0 0 -0 0</pose>
        <geometry>
          <box>
            <size>0.001 0.001 0.001</size>
          </box>
        </geometry>
        <material>
          <script>
            <name>Gazebo/DarkGrey</name>
            <uri>file://media/materials/scripts/gazebo.material</uri>
          </script>
        </material>
      </visual>
      <visual name='base_fixed_joint_lump__trunk_visual_1'>
        <pose>0 0 0 0 -0 0</pose>
        <geometry>
          <mesh>
            <scale>1 1 1</scale>
            <uri>model://b1_description/meshes/trunk.dae</uri>
          </mesh>
        </geometry>
        <material>
          <script>
            <name>Gazebo/DarkGrey</name>
            <uri>file://media/materials/scripts/gazebo.material</uri>
          </script>
        </material>
      </visual>
      <visual name='base_fixed_joint_lump__imu_link_visual_2'>
        <pose>0 0 0 0 -0 0</pose>
        <geometry>
          <box>
            <size>0.001 0.001 0.001</size>
          </box>
        </geometry>
        <material>
          <script>
            <name>Gazebo/Red</name>
            <uri>file://media/materials/scripts/gazebo.material</uri>
          </script>
        </material>
      </visual>
      <visual name='base_fixed_joint_lump__sim_collider_visual_3'>
        <pose>0 0 0 0 -0 0</pose>
        <geometry>
          <box>
            <size>0.65 0.45 0.1</size>
          </box>
        </geometry>
        <material>
          <script>
            <name>Gazebo/Orange</name>
            <uri>file://media/materials/scripts/gazebo.material</uri>
          </script>
        </material>
      </visual>
      <gravity>1</gravity>
      <gravity>1</gravity>
      <sensor name='imu_sensor' type='imu'>
        <always_on>1</always_on>
        <update_rate>1000</update_rate>
        <visualize>1</visualize>
        <topic>__default_topic__</topic>
        <plugin name='imu_plugin' filename='libgazebo_ros_imu_sensor.so'>
          <topicName>trunk_imu</topicName>
          <bodyName>imu_link</bodyName>
          <updateRateHZ>1000.0</updateRateHZ>
          <gaussianNoise>0.0</gaussianNoise>
          <xyzOffset>0 0 0</xyzOffset>
          <rpyOffset>0 0 0</rpyOffset>
          <frameName>imu_link</frameName>
        </plugin>
        <pose>0 0 0 0 -0 0</pose>
      </sensor>
      <sensor name='sim_collider_link_contact_sensor' type='contact'>
        <always_on>1</always_on>
        <update_rate>100</update_rate>
        <contact>
          <collision>base_link_fixed_joint_lump__sim_collider_collision_1</collision>
          <topic>__default_topic__</topic>
        </contact>
        <plugin name='gazebo_ros_sim_collider_controller' filename='libgazebo_ros_bumper.so'>
          <always_on>1</always_on>
          <update_rate>100</update_rate>
          <frameName>world</frameName>
          <bumperTopicName>bumper_contact_state</bumperTopicName>
        </plugin>
        <pose>0 0 0 0 -0 0</pose>
      </sensor>
    </link>
    <joint name='FL_hip_joint' type='revolute'>
      <pose relative_to='base'>0.3455 0.072 0 0 -0 0</pose>
      <parent>base</parent>
      <child>FL_hip</child>
      <axis>
        <xyz>1 0 0</xyz>
        <limit>
          <lower>-0.75</lower>
          <upper>0.75</upper>
          <effort>100</effort>
          <velocity>20</velocity>
        </limit>
        <dynamics>
          <damping>0</damping>
          <friction>0</friction>
          <spring_reference>0</spring_reference>
          <spring_stiffness>0</spring_stiffness>
        </dynamics>
      </axis>
    </joint>
    <link name='FL_hip'>
      <pose relative_to='FL_hip_joint'>0 0 0 0 -0 0</pose>
      <inertial>
        <pose>-0.022191 0.015144 -1.5e-05 0 -0 0</pose>
        <mass>1.993</mass>
        <inertia>
          <ixx>0.00290389</ixx>
          <ixy>-7.185e-05</ixy>
          <ixz>-1.262e-06</ixz>
          <iyy>0.00490752</iyy>
          <iyz>-1.75e-06</iyz>
          <izz>0.00558694</izz>
        </inertia>
      </inertial>
      <collision name='FL_hip_collision'>
        <pose>0 0.12675 0 1.5708 -0 0</pose>
        <geometry>
          <cylinder>
            <length>0.04</length>
            <radius>0.09</radius>
          </cylinder>
        </geometry>
        <surface>
          <contact>
            <ode/>
          </contact>
          <friction>
            <ode>
              <mu>0.2</mu>
              <mu2>0.2</mu2>
            </ode>
          </friction>
        </surface>
      </collision>
      <visual name='FL_hip_visual'>
        <pose>0 0 0 0 -0 0</pose>
        <geometry>
          <mesh>
            <scale>1 1 1</scale>
            <uri>model://b1_description/meshes/hip.dae</uri>
          </mesh>
        </geometry>
        <material>
          <script>
            <name>Gazebo/DarkGrey</name>
            <uri>file://media/materials/scripts/gazebo.material</uri>
          </script>
        </material>
      </visual>
    </link>
    <joint name='FL_thigh_joint' type='revolute'>
      <pose relative_to='FL_hip'>0 0.12675 0 0 -0 0</pose>
      <parent>FL_hip</parent>
      <child>FL_thigh</child>
      <axis>
        <xyz>0 1 0</xyz>
        <limit>
          <effort>100</effort>
          <velocity>20</velocity>
          <lower>-1e+16</lower>
          <upper>1e+16</upper>
        </limit>
        <dynamics>
          <damping>0</damping>
          <friction>0</friction>
          <spring_reference>0</spring_reference>
          <spring_stiffness>0</spring_stiffness>
        </dynamics>
      </axis>
    </joint>
    <link name='FL_thigh'>
      <pose relative_to='FL_thigh_joint'>0 0 0 0 -0 0</pose>
      <inertial>
        <pose>-0.005607 -0.003877 -0.048199 0 -0 0</pose>
        <mass>0.639</mass>
        <inertia>
          <ixx>0.0056668</ixx>
          <ixy>3.597e-06</ixy>
          <ixz>0.000491446</ixz>
          <iyy>0.00584723</iyy>
          <iyz>1.0086e-05</iyz>
          <izz>0.000369811</izz>
        </inertia>
      </inertial>
      <collision name='FL_thigh_collision'>
        <pose>0 0 -0.175 0 1.5708 0</pose>
        <geometry>
          <box>
            <size>0.35 0.05 0.08</size>
          </box>
        </geometry>
        <surface>
          <contact>
            <ode>
              <kp>1e+06</kp>
              <kd>1</kd>
            </ode>
          </contact>
          <friction>
            <ode>
              <mu>0.2</mu>
              <mu2>0.2</mu2>
            </ode>
          </friction>
        </surface>
      </collision>
      <visual name='FL_thigh_visual'>
        <pose>0 0 0 0 -0 0</pose>
        <geometry>
          <mesh>
            <scale>1 1 1</scale>
            <uri>model://b1_description/meshes/thigh.dae</uri>
          </mesh>
        </geometry>
        <material>
          <script>
            <name>Gazebo/DarkGrey</name>
            <uri>file://media/materials/scripts/gazebo.material</uri>
          </script>
        </material>
      </visual>
      <self_collide>1</self_collide>
    </link>
    <joint name='FL_calf_joint' type='revolute'>
      <pose relative_to='FL_thigh'>0 0 -0.35 0 -0 0</pose>
      <parent>FL_thigh</parent>
      <child>FL_calf</child>
      <axis>
        <xyz>0 1 0</xyz>
        <limit>
          <lower>-2.6</lower>
          <upper>-0.6</upper>
          <effort>100</effort>
          <velocity>20</velocity>
        </limit>
        <dynamics>
          <damping>0</damping>
          <friction>0</friction>
          <spring_reference>0</spring_reference>
          <spring_stiffness>0</spring_stiffness>
        </dynamics>
      </axis>
    </joint>
    <link name='FL_calf'>
      <pose relative_to='FL_calf_joint'>0 0 0 0 -0 0</pose>
      <inertial>
        <pose>0.002156 4.9e-05 -0.189143 0 -0 0</pose>
        <mass>0.267</mass>
        <inertia>
          <ixx>0.00838226</ixx>
          <ixy>-1.11499e-08</ixy>
          <ixz>-0.000114792</ixz>
          <iyy>0.00839641</iyy>
          <iyz>-1.94404e-06</iyz>
          <izz>7.79479e-05</izz>
        </inertia>
      </inertial>
      <collision name='FL_calf_collision'>
        <pose>0 0 -0.175 0 1.5708 0</pose>
        <geometry>
          <box>
            <size>0.35 0.04 0.03</size>
          </box>
        </geometry>
        <surface>
          <contact>
            <ode/>
          </contact>
          <friction>
            <ode>
              <mu>0.2</mu>
              <mu2>0.2</mu2>
            </ode>
          </friction>
        </surface>
      </collision>
      <collision name='FL_calf_fixed_joint_lump__FL_foot_collision_1'>
        <pose>0 0 -0.35 0 -0 0</pose>
        <geometry>
          <sphere>
            <radius>0.04</radius>
          </sphere>
        </geometry>
        <surface>
          <contact>
            <ode>
              <kp>1e+06</kp>
              <kd>1</kd>
            </ode>
          </contact>
          <friction>
            <ode>
              <mu>0.6</mu>
              <mu2>0.6</mu2>
            </ode>
          </friction>
        </surface>
      </collision>
      <visual name='FL_calf_visual'>
        <pose>0 0 0 0 -0 0</pose>
        <geometry>
          <mesh>
            <scale>1 1 1</scale>
            <uri>model://b1_description/meshes/calf.dae</uri>
          </mesh>
        </geometry>
        <material>
          <script>
            <name>Gazebo/DarkGrey</name>
            <uri>file://media/materials/scripts/gazebo.material</uri>
          </script>
        </material>
      </visual>
      <visual name='FL_calf_fixed_joint_lump__FL_foot_visual_1'>
        <pose>0 0 -0.35 0 -0 0</pose>
        <geometry>
          <sphere>
            <radius>0.03</radius>
          </sphere>
        </geometry>
        <plugin name='drawForcePlugin' filename='libunitreeDrawForcePlugin.so'>
          <topicName>FL_foot_contact</topicName>
        </plugin>
        <material>
          <script>
            <name>Gazebo/DarkGrey</name>
            <uri>file://media/materials/scripts/gazebo.material</uri>
          </script>
        </material>
      </visual>
      <sensor name='FL_foot_contact' type='contact'>
        <update_rate>100</update_rate>
        <plugin name='contactPlugin' filename='libunitreeFootContactPlugin.so'/>
        <contact>
          <collision>FL_calf_fixed_joint_lump__FL_foot_collision_1</collision>
          <topic>__default_topic__</topic>
        </contact>
      </sensor>
      <self_collide>1</self_collide>
      <self_collide>1</self_collide>
    </link>
    <joint name='FR_hip_joint' type='revolute'>
      <pose relative_to='base'>0.3455 -0.072 0 0 -0 0</pose>
      <parent>base</parent>
      <child>FR_hip</child>
      <axis>
        <xyz>1 0 0</xyz>
        <limit>
          <lower>-0.75</lower>
          <upper>0.75</upper>
          <effort>100</effort>
          <velocity>20</velocity>
        </limit>
        <dynamics>
          <damping>0</damping>
          <friction>0</friction>
          <spring_reference>0</spring_reference>
          <spring_stiffness>0</spring_stiffness>
        </dynamics>
      </axis>
    </joint>
    <link name='FR_hip'>
      <pose relative_to='FR_hip_joint'>0 0 0 0 -0 0</pose>
      <inertial>
        <pose>-0.022191 -0.015144 -1.5e-05 0 -0 0</pose>
        <mass>1.993</mass>
        <inertia>
          <ixx>0.00290389</ixx>
          <ixy>7.185e-05</ixy>
          <ixz>-1.262e-06</ixz>
          <iyy>0.00490752</iyy>
          <iyz>1.75e-06</iyz>
          <izz>0.00558694</izz>
        </inertia>
      </inertial>
      <collision name='FR_hip_collision'>
        <pose>0 -0.12675 0 1.5708 -0 0</pose>
        <geometry>
          <cylinder>
            <length>0.04</length>
            <radius>0.09</radius>
          </cylinder>
        </geometry>
        <surface>
          <contact>
            <ode/>
          </contact>
          <friction>
            <ode>
              <mu>0.2</mu>
              <mu2>0.2</mu2>
            </ode>
          </friction>
        </surface>
      </collision>
      <visual name='FR_hip_visual'>
        <pose>0 0 0 -3.14159 0 0</pose>
        <geometry>
          <mesh>
            <scale>1 1 1</scale>
            <uri>model://b1_description/meshes/hip.dae</uri>
          </mesh>
        </geometry>
        <material>
          <script>
            <name>Gazebo/DarkGrey</name>
            <uri>file://media/materials/scripts/gazebo.material</uri>
          </script>
        </material>
      </visual>
    </link>
    <joint name='FR_thigh_joint' type='revolute'>
      <pose relative_to='FR_hip'>0 -0.12675 0 0 -0 0</pose>
      <parent>FR_hip</parent>
      <child>FR_thigh</child>
      <axis>
        <xyz>0 1 0</xyz>
        <limit>
          <effort>100</effort>
          <velocity>20</velocity>
          <lower>-1e+16</lower>
          <upper>1e+16</upper>
        </limit>
        <dynamics>
          <damping>0</damping>
          <friction>0</friction>
          <spring_reference>0</spring_reference>
          <spring_stiffness>0</spring_stiffness>
        </dynamics>
      </axis>
    </joint>
    <link name='FR_thigh'>
      <pose relative_to='FR_thigh_joint'>0 0 0 0 -0 0</pose>
      <inertial>
        <pose>-0.005607 0.003877 -0.048199 0 -0 0</pose>
        <mass>0.639</mass>
        <inertia>
          <ixx>0.0056668</ixx>
          <ixy>-3.597e-06</ixy>
          <ixz>0.000491446</ixz>
          <iyy>0.00584723</iyy>
          <iyz>-1.0086e-05</iyz>
          <izz>0.000369811</izz>
        </inertia>
      </inertial>
      <collision name='FR_thigh_collision'>
        <pose>0 0 -0.175 0 1.5708 0</pose>
        <geometry>
          <box>
            <size>0.35 0.05 0.08</size>
          </box>
        </geometry>
        <surface>
          <contact>
            <ode>
              <kp>1e+06</kp>
              <kd>1</kd>
            </ode>
          </contact>
          <friction>
            <ode>
              <mu>0.2</mu>
              <mu2>0.2</mu2>
            </ode>
          </friction>
        </surface>
      </collision>
      <visual name='FR_thigh_visual'>
        <pose>0 0 0 0 -0 0</pose>
        <geometry>
          <mesh>
            <scale>1 1 1</scale>
            <uri>model://b1_description/meshes/thigh_mirror.dae</uri>
          </mesh>
        </geometry>
        <material>
          <script>
            <name>Gazebo/DarkGrey</name>
            <uri>file://media/materials/scripts/gazebo.material</uri>
          </script>
        </material>
      </visual>
      <self_collide>1</self_collide>
    </link>
    <joint name='FR_calf_joint' type='revolute'>
      <pose relative_to='FR_thigh'>0 0 -0.35 0 -0 0</pose>
      <parent>FR_thigh</parent>
      <child>FR_calf</child>
      <axis>
        <xyz>0 1 0</xyz>
        <limit>
          <lower>-2.6</lower>
          <upper>-0.6</upper>
          <effort>100</effort>
          <velocity>20</velocity>
        </limit>
        <dynamics>
          <damping>0</damping>
          <friction>0</friction>
          <spring_reference>0</spring_reference>
          <spring_stiffness>0</spring_stiffness>
        </dynamics>
      </axis>
    </joint>
    <link name='FR_calf'>
      <pose relative_to='FR_calf_joint'>0 0 0 0 -0 0</pose>
      <inertial>
        <pose>0.002156 4.9e-05 -0.189143 0 -0 0</pose>
        <mass>0.267</mass>
        <inertia>
          <ixx>0.00838226</ixx>
          <ixy>-1.11499e-08</ixy>
          <ixz>-0.000114792</ixz>
          <iyy>0.00839641</iyy>
          <iyz>-1.94404e-06</iyz>
          <izz>7.79479e-05</izz>
        </inertia>
      </inertial>
      <collision name='FR_calf_collision'>
        <pose>0 0 -0.175 0 1.5708 0</pose>
        <geometry>
          <box>
            <size>0.35 0.04 0.03</size>
          </box>
        </geometry>
        <surface>
          <contact>
            <ode/>
          </contact>
          <friction>
            <ode>
              <mu>0.2</mu>
              <mu2>0.2</mu2>
            </ode>
          </friction>
        </surface>
      </collision>
      <collision name='FR_calf_fixed_joint_lump__FR_foot_collision_1'>
        <pose>0 0 -0.35 0 -0 0</pose>
        <geometry>
          <sphere>
            <radius>0.04</radius>
          </sphere>
        </geometry>
        <surface>
          <contact>
            <ode>
              <kp>1e+06</kp>
              <kd>1</kd>
            </ode>
          </contact>
          <friction>
            <ode>
              <mu>0.6</mu>
              <mu2>0.6</mu2>
            </ode>
          </friction>
        </surface>
      </collision>
      <visual name='FR_calf_visual'>
        <pose>0 0 0 0 -0 0</pose>
        <geometry>
          <mesh>
            <scale>1 1 1</scale>
            <uri>model://b1_description/meshes/calf.dae</uri>
          </mesh>
        </geometry>
        <material>
          <script>
            <name>Gazebo/DarkGrey</name>
            <uri>file://media/materials/scripts/gazebo.material</uri>
          </script>
        </material>
      </visual>
      <visual name='FR_calf_fixed_joint_lump__FR_foot_visual_1'>
        <pose>0 0 -0.35 0 -0 0</pose>
        <geometry>
          <sphere>
            <radius>0.03</radius>
          </sphere>
        </geometry>
        <plugin name='drawForcePlugin' filename='libunitreeDrawForcePlugin.so'>
          <topicName>FR_foot_contact</topicName>
        </plugin>
        <material>
          <script>
            <name>Gazebo/DarkGrey</name>
            <uri>file://media/materials/scripts/gazebo.material</uri>
          </script>
        </material>
      </visual>
      <sensor name='FR_foot_contact' type='contact'>
        <update_rate>100</update_rate>
        <plugin name='contactPlugin' filename='libunitreeFootContactPlugin.so'/>
        <contact>
          <collision>FR_calf_fixed_joint_lump__FR_foot_collision_1</collision>
          <topic>__default_topic__</topic>
        </contact>
      </sensor>
      <self_collide>1</self_collide>
      <self_collide>1</self_collide>
    </link>
    <joint name='RL_hip_joint' type='revolute'>
      <pose relative_to='base'>-0.3455 0.072 0 0 -0 0</pose>
      <parent>base</parent>
      <child>RL_hip</child>
      <axis>
        <xyz>1 0 0</xyz>
        <limit>
          <lower>-0.75</lower>
          <upper>0.75</upper>
          <effort>100</effort>
          <velocity>20</velocity>
        </limit>
        <dynamics>
          <damping>0</damping>
          <friction>0</friction>
          <spring_reference>0</spring_reference>
          <spring_stiffness>0</spring_stiffness>
        </dynamics>
      </axis>
    </joint>
    <link name='RL_hip'>
      <pose relative_to='RL_hip_joint'>0 0 0 0 -0 0</pose>
      <inertial>
        <pose>0.022191 0.015144 -1.5e-05 0 -0 0</pose>
        <mass>1.993</mass>
        <inertia>
          <ixx>0.00290389</ixx>
          <ixy>7.185e-05</ixy>
          <ixz>1.262e-06</ixz>
          <iyy>0.00490752</iyy>
          <iyz>-1.75e-06</iyz>
          <izz>0.00558694</izz>
        </inertia>
      </inertial>
      <collision name='RL_hip_collision'>
        <pose>0 0.12675 0 1.5708 -0 0</pose>
        <geometry>
          <cylinder>
            <length>0.04</length>
            <radius>0.09</radius>
          </cylinder>
        </geometry>
        <surface>
          <contact>
            <ode/>
          </contact>
          <friction>
            <ode>
              <mu>0.2</mu>
              <mu2>0.2</mu2>
            </ode>
          </friction>
        </surface>
      </collision>
      <visual name='RL_hip_visual'>
        <pose>0 0 0 3.14159 -0 3.14159</pose>
        <geometry>
          <mesh>
            <scale>1 1 1</scale>
            <uri>model://b1_description/meshes/hip.dae</uri>
          </mesh>
        </geometry>
        <material>
          <script>
            <name>Gazebo/DarkGrey</name>
            <uri>file://media/materials/scripts/gazebo.material</uri>
          </script>
        </material>
      </visual>
    </link>
    <joint name='RL_thigh_joint' type='revolute'>
      <pose relative_to='RL_hip'>0 0.12675 0 0 -0 0</pose>
      <parent>RL_hip</parent>
      <child>RL_thigh</child>
      <axis>
        <xyz>0 1 0</xyz>
        <limit>
          <effort>100</effort>
          <velocity>20</velocity>
          <lower>-1e+16</lower>
          <upper>1e+16</upper>
        </limit>
        <dynamics>
          <damping>0</damping>
          <friction>0</friction>
          <spring_reference>0</spring_reference>
          <spring_stiffness>0</spring_stiffness>
        </dynamics>
      </axis>
    </joint>
    <link name='RL_thigh'>
      <pose relative_to='RL_thigh_joint'>0 0 0 0 -0 0</pose>
      <inertial>
        <pose>-0.005607 -0.003877 -0.048199 0 -0 0</pose>
        <mass>0.639</mass>
        <inertia>
          <ixx>0.0056668</ixx>
          <ixy>3.597e-06</ixy>
          <ixz>0.000491446</ixz>
          <iyy>0.00584723</iyy>
          <iyz>1.0086e-05</iyz>
          <izz>0.000369811</izz>
        </inertia>
      </inertial>
      <collision name='RL_thigh_collision'>
        <pose>0 0 -0.175 0 1.5708 0</pose>
        <geometry>
          <box>
            <size>0.35 0.05 0.08</size>
          </box>
        </geometry>
        <surface>
          <contact>
            <ode>
              <kp>1e+06</kp>
              <kd>1</kd>
            </ode>
          </contact>
          <friction>
            <ode>
              <mu>0.2</mu>
              <mu2>0.2</mu2>
            </ode>
          </friction>
        </surface>
      </collision>
      <visual name='RL_thigh_visual'>
        <pose>0 0 0 0 -0 0</pose>
        <geometry>
          <mesh>
            <scale>1 1 1</scale>
            <uri>model://b1_description/meshes/thigh.dae</uri>
          </mesh>
        </geometry>
        <material>
          <script>
            <name>Gazebo/DarkGrey</name>
            <uri>file://media/materials/scripts/gazebo.material</uri>
          </script>
        </material>
      </visual>
      <self_collide>1</self_collide>
    </link>
    <joint name='RL_calf_joint' type='revolute'>
      <pose relative_to='RL_thigh'>0 0 -0.35 0 -0 0</pose>
      <parent>RL_thigh</parent>
      <child>RL_calf</child>
      <axis>
        <xyz>0 1 0</xyz>
        <limit>
          <lower>-2.6</lower>
          <upper>-0.6</upper>
          <effort>100</effort>
          <velocity>20</velocity>
        </limit>
        <dynamics>
          <damping>0</damping>
          <friction>0</friction>
          <spring_reference>0</spring_reference>
          <spring_stiffness>0</spring_stiffness>
        </dynamics>
      </axis>
    </joint>
    <link name='RL_calf'>
      <pose relative_to='RL_calf_joint'>0 0 0 0 -0 0</pose>
      <inertial>
        <pose>0.002156 4.9e-05 -0.189143 0 -0 0</pose>
        <mass>0.267</mass>
        <inertia>
          <ixx>0.00838226</ixx>
          <ixy>-1.11499e-08</ixy>
          <ixz>-0.000114792</ixz>
          <iyy>0.00839641</iyy>
          <iyz>-1.94404e-06</iyz>
          <izz>7.79479e-05</izz>
        </inertia>
      </inertial>
      <collision name='RL_calf_collision'>
        <pose>0 0 -0.175 0 1.5708 0</pose>
        <geometry>
          <box>
            <size>0.35 0.04 0.03</size>
          </box>
        </geometry>
        <surface>
          <contact>
            <ode/>
          </contact>
          <friction>
            <ode>
              <mu>0.2</mu>
              <mu2>0.2</mu2>
            </ode>
          </friction>
        </surface>
      </collision>
      <collision name='RL_calf_fixed_joint_lump__RL_foot_collision_1'>
        <pose>0 0 -0.35 0 -0 0</pose>
        <geometry>
          <sphere>
            <radius>0.04</radius>
          </sphere>
        </geometry>
        <surface>
          <contact>
            <ode>
              <kp>1e+06</kp>
              <kd>1</kd>
            </ode>
          </contact>
          <friction>
            <ode>
              <mu>0.6</mu>
              <mu2>0.6</mu2>
            </ode>
          </friction>
        </surface>
      </collision>
      <visual name='RL_calf_visual'>
        <pose>0 0 0 0 -0 0</pose>
        <geometry>
          <mesh>
            <scale>1 1 1</scale>
            <uri>model://b1_description/meshes/calf.dae</uri>
          </mesh>
        </geometry>
        <material>
          <script>
            <name>Gazebo/DarkGrey</name>
            <uri>file://media/materials/scripts/gazebo.material</uri>
          </script>
        </material>
      </visual>
      <visual name='RL_calf_fixed_joint_lump__RL_foot_visual_1'>
        <pose>0 0 -0.35 0 -0 0</pose>
        <geometry>
          <sphere>
            <radius>0.03</radius>
          </sphere>
        </geometry>
        <plugin name='drawForcePlugin' filename='libunitreeDrawForcePlugin.so'>
          <topicName>RL_foot_contact</topicName>
        </plugin>
        <material>
          <script>
            <name>Gazebo/DarkGrey</name>
            <uri>file://media/materials/scripts/gazebo.material</uri>
          </script>
        </material>
      </visual>
      <sensor name='RL_foot_contact' type='contact'>
        <update_rate>100</update_rate>
        <plugin name='contactPlugin' filename='libunitreeFootContactPlugin.so'/>
        <contact>
          <collision>RL_calf_fixed_joint_lump__RL_foot_collision_1</collision>
          <topic>__default_topic__</topic>
        </contact>
      </sensor>
      <self_collide>1</self_collide>
      <self_collide>1</self_collide>
    </link>
    <joint name='RR_hip_joint' type='revolute'>
      <pose relative_to='base'>-0.3455 -0.072 0 0 -0 0</pose>
      <parent>base</parent>
      <child>RR_hip</child>
      <axis>
        <xyz>1 0 0</xyz>
        <limit>
          <lower>-0.75</lower>
          <upper>0.75</upper>
          <effort>100</effort>
          <velocity>20</velocity>
        </limit>
        <dynamics>
          <damping>0</damping>
          <friction>0</friction>
          <spring_reference>0</spring_reference>
          <spring_stiffness>0</spring_stiffness>
        </dynamics>
      </axis>
    </joint>
    <link name='RR_hip'>
      <pose relative_to='RR_hip_joint'>0 0 0 0 -0 0</pose>
      <inertial>
        <pose>0.022191 -0.015144 -1.5e-05 0 -0 0</pose>
        <mass>1.993</mass>
        <inertia>
          <ixx>0.00290389</ixx>
          <ixy>-7.185e-05</ixy>
          <ixz>1.262e-06</ixz>
          <iyy>0.00490752</iyy>
          <iyz>1.75e-06</iyz>
          <izz>0.00558694</izz>
        </inertia>
      </inertial>
      <collision name='RR_hip_collision'>
        <pose>0 -0.12675 0 1.5708 -0 0</pose>
        <geometry>
          <cylinder>
            <length>0.04</length>
            <radius>0.09</radius>
          </cylinder>
        </geometry>
        <surface>
          <contact>
            <ode/>
          </contact>
          <friction>
            <ode>
              <mu>0.2</mu>
              <mu2>0.2</mu2>
            </ode>
          </friction>
        </surface>
      </collision>
      <visual name='RR_hip_visual'>
        <pose>0 0 0 0 -0 3.14159</pose>
        <geometry>
          <mesh>
            <scale>1 1 1</scale>
            <uri>model://b1_description/meshes/hip.dae</uri>
          </mesh>
        </geometry>
        <material>
          <script>
            <name>Gazebo/DarkGrey</name>
            <uri>file://media/materials/scripts/gazebo.material</uri>
          </script>
        </material>
      </visual>
    </link>
    <joint name='RR_thigh_joint' type='revolute'>
      <pose relative_to='RR_hip'>0 -0.12675 0 0 -0 0</pose>
      <parent>RR_hip</parent>
      <child>RR_thigh</child>
      <axis>
        <xyz>0 1 0</xyz>
        <limit>
          <effort>100</effort>
          <velocity>20</velocity>
          <lower>-1e+16</lower>
          <upper>1e+16</upper>
        </limit>
        <dynamics>
          <damping>0</damping>
          <friction>0</friction>
          <spring_reference>0</spring_reference>
          <spring_stiffness>0</spring_stiffness>
        </dynamics>
      </axis>
    </joint>
    <link name='RR_thigh'>
      <pose relative_to='RR_thigh_joint'>0 0 0 0 -0 0</pose>
      <inertial>
        <pose>-0.005607 0.003877 -0.048199 0 -0 0</pose>
        <mass>0.639</mass>
        <inertia>
          <ixx>0.0056668</ixx>
          <ixy>-3.597e-06</ixy>
          <ixz>0.000491446</ixz>
          <iyy>0.00584723</iyy>
          <iyz>-1.0086e-05</iyz>
          <izz>0.000369811</izz>
        </inertia>
      </inertial>
      <collision name='RR_thigh_collision'>
        <pose>0 0 -0.175 0 1.5708 0</pose>
        <geometry>
          <box>
            <size>0.35 0.05 0.08</size>
          </box>
        </geometry>
        <surface>
          <contact>
            <ode>
              <kp>1e+06</kp>
              <kd>1</kd>
            </ode>
          </contact>
          <friction>
            <ode>
              <mu>0.2</mu>
              <mu2>0.2</mu2>
            </ode>
          </friction>
        </surface>
      </collision>
      <visual name='RR_thigh_visual'>
        <pose>0 0 0 0 -0 0</pose>
        <geometry>
          <mesh>
            <scale>1 1 1</scale>
            <uri>model://b1_description/meshes/thigh_mirror.dae</uri>
          </mesh>
        </geometry>
        <material>
          <script>
            <name>Gazebo/DarkGrey</name>
            <uri>file://media/materials/scripts/gazebo.material</uri>
          </script>
        </material>
      </visual>
      <self_collide>1</self_collide>
    </link>
    <joint name='RR_calf_joint' type='revolute'>
      <pose relative_to='RR_thigh'>0 0 -0.35 0 -0 0</pose>
      <parent>RR_thigh</parent>
      <child>RR_calf</child>
      <axis>
        <xyz>0 1 0</xyz>
        <limit>
          <lower>-2.6</lower>
          <upper>-0.6</upper>
          <effort>100</effort>
          <velocity>20</velocity>
        </limit>
        <dynamics>
          <damping>0</damping>
          <friction>0</friction>
          <spring_reference>0</spring_reference>
          <spring_stiffness>0</spring_stiffness>
        </dynamics>
      </axis>
    </joint>
    <link name='RR_calf'>
      <pose relative_to='RR_calf_joint'>0 0 0 0 -0 0</pose>
      <inertial>
        <pose>0.002156 4.9e-05 -0.189143 0 -0 0</pose>
        <mass>0.267</mass>
        <inertia>
          <ixx>0.00838226</ixx>
          <ixy>-1.11499e-08</ixy>
          <ixz>-0.000114792</ixz>
          <iyy>0.00839641</iyy>
          <iyz>-1.94404e-06</iyz>
          <izz>7.79479e-05</izz>
        </inertia>
      </inertial>
      <collision name='RR_calf_collision'>
        <pose>0 0 -0.175 0 1.5708 0</pose>
        <geometry>
          <box>
            <size>0.35 0.04 0.03</size>
          </box>
        </geometry>
        <surface>
          <contact>
            <ode/>
          </contact>
          <friction>
            <ode>
              <mu>0.2</mu>
              <mu2>0.2</mu2>
            </ode>
          </friction>
        </surface>
      </collision>
      <collision name='RR_calf_fixed_joint_lump__RR_foot_collision_1'>
        <pose>0 0 -0.35 0 -0 0</pose>
        <geometry>
          <sphere>
            <radius>0.04</radius>
          </sphere>
        </geometry>
        <surface>
          <contact>
            <ode>
              <kp>1e+06</kp>
              <kd>1</kd>
            </ode>
          </contact>
          <friction>
            <ode>
              <mu>0.6</mu>
              <mu2>0.6</mu2>
            </ode>
          </friction>
        </surface>
      </collision>
      <visual name='RR_calf_visual'>
        <pose>0 0 0 0 -0 0</pose>
        <geometry>
          <mesh>
            <scale>1 1 1</scale>
            <uri>model://b1_description/meshes/calf.dae</uri>
          </mesh>
        </geometry>
        <material>
          <script>
            <name>Gazebo/DarkGrey</name>
            <uri>file://media/materials/scripts/gazebo.material</uri>
          </script>
        </material>
      </visual>
      <visual name='RR_calf_fixed_joint_lump__RR_foot_visual_1'>
        <pose>0 0 -0.35 0 -0 0</pose>
        <geometry>
          <sphere>
            <radius>0.03</radius>
          </sphere>
        </geometry>
        <plugin name='drawForcePlugin' filename='libunitreeDrawForcePlugin.so'>
          <topicName>RR_foot_contact</topicName>
        </plugin>
        <material>
          <script>
            <name>Gazebo/DarkGrey</name>
            <uri>file://media/materials/scripts/gazebo.material</uri>
          </script>
        </material>
      </visual>
      <sensor name='RR_foot_contact' type='contact'>
        <update_rate>100</update_rate>
        <plugin name='contactPlugin' filename='libunitreeFootContactPlugin.so'/>
        <contact>
          <collision>RR_calf_fixed_joint_lump__RR_foot_collision_1</collision>
          <topic>__default_topic__</topic>
        </contact>
      </sensor>
      <self_collide>1</self_collide>
      <self_collide>1</self_collide>
    </link>
    <plugin name='gazebo_ros_control' filename='libgazebo_ros_control.so'>
      <robotNamespace>/b1</robotNamespace>
      <robotSimType>gazebo_ros_control/DefaultRobotHWSim</robotSimType>
    </plugin>
    <static>0</static>
    <plugin name='gazebo_ros_force' filename='libgazebo_ros_force.so'>
      <topicName>/apply_force/trunk</topicName>
      <bodyName>base</bodyName>
      <xyzOffset>0 0 0</xyzOffset>
      <rpyOffset>0 -0 0</rpyOffset>
      <ignition::corrected_offsets>1</ignition::corrected_offsets>
    </plugin>
  </model>
</sdf>
